Workbook

Sheet Set a analizar
B2: Story | C2: Beam | D2: Unique Name | E2: Output Case | F2: Case Type | G2: Step Type | H2: Station | I2: P | J2: V2 | K2: V3 | L2: T | M2: M2 | N2: M3 | O2: Element | P2: Elem Station | Q2: Location
H3: m | I3: tonf | J3: tonf | K3: tonf | L3: tonf-m | M3: tonf-m | N3: tonf-m | P3: m
B4: -1 | C4: B4 | D4: 4 | E4: PP | F4: LinStatic | H4: 0 | I4: 0 | J4: -0.9952 | K4: 0 | L4: 0 | M4: 0 | N4: 0 | O4: 46026 | P4: 0
B5: -1 | C5: B4 | D5: 4 | E5: PP | F5: LinStatic | H5: 0.4575 | I5: 0 | J5: -0.8523 | K5: 0 | L5: 0 | M5: 0 | N5: 0.4226 | O5: 46026 | P5: 0.4575
B6: -1 | C6: B4 | D6: 4 | E6: PP | F6: LinStatic | H6: 0.915 | I6: 0 | J6: -0.7093 | K6: 0 | L6: 0 | M6: 0 | N6: 0.7798 | O6: 46026 | P6: 0.915
B7: -1 | C7: B4 | D7: 4 | E7: PP | F7: LinStatic | H7: 0.915 | I7: 0 | J7: -1.6428 | K7: 0 | L7: 0 | M7: 0 | N7: 1.013 | O7: 46057 | P7: 0
B8: -1 | C8: B4 | D8: 4 | E8: PP | F8: LinStatic | H8: 1.3725 | I8: 0 | J8: -1.4999 | K8: 0 | L8: 0 | M8: 0 | N8: 1.7319 | O8: 46057 | P8: 0.4575
B9: -1 | C9: B4 | D9: 4 | E9: PP | F9: LinStatic | H9: 1.83 | I9: 0 | J9: -1.3569 | K9: 0 | L9: 0 | M9: 0 | N9: 2.3854 | O9: 46057 | P9: 0.915
B10: -1 | C10: B4 | D10: 4 | E10: PP | F10: LinStatic | H10: 1.83 | I10: 0 | J10: -0.3967 | K10: 0 | L10: 0 | M10: 0 | N10: 2.4161 | O10: 46085 | P10: 0
B11: -1 | C11: B4 | D11: 4 | E11: PP | F11: LinStatic | H11: 2.2875 | I11: 0 | J11: -0.2538 | K11: 0 | L11: 0 | M11: 0 | N11: 2.5649 | O11: 46085 | P11: 0.4575
B12: -1 | C12: B4 | D12: 4 | E12: PP | F12: LinStatic | H12: 2.745 | I12: 0 | J12: -0.1108 | K12: 0 | L12: 0 | M12: 0 | N12: 2.6483 | O12: 46085 | P12: 0.915
B13: -1 | C13: B4 | D13: 4 | E13: PP | F13: LinStatic | H13: 2.745 | I13: 0 | J13: 1.108 | K13: 0 | L13: 0 | M13: 0 | N13: 2.6285 | O13: 46116 | P13: 0
B14: -1 | C14: B4 | D14: 4 | E14: PP | F14: LinStatic | H14: 3.2025 | I14: 0 | J14: 1.2509 | K14: 0 | L14: 0 | M14: 0 | N14: 2.0889 | O14: 46116 | P14: 0.4575
B15: -1 | C15: B4 | D15: 4 | E15: PP | F15: LinStatic | H15: 3.66 | I15: 0 | J15: 1.3939 | K15: 0 | L15: 0 | M15: 0 | N15: 1.4839 | O15: 46116 | P15: 0.915
... B39: -1 | C39: B4 | D39: 4 | E39: SC | F39: LinStatic | H39: 5.34 | I39: 0 | J39: 3.5104 | K39: 0 | L39: 0 | M39: 0 | N39: -3.6601 | O39: 46177 | P39: 0.765
B40: -1 | C40: B4 | D40: 4 | E40: SX | F40: LinRespSpec | G40: Max | H40: 0 | I40: 0 | J40: 0.1101 | K40: 0 | L40: 0 | M40: 0 | N40: 0 | O40: 46026 | P40: 0
B41: -1 | C41: B4 | D41: 4 | E41: SX | F41: LinRespSpec | G41: Max | H41: 0.4575 | I41: 0 | J41: 0.1101 | K41: 0 | L41: 0 | M41: 0 | N41: 0.0504 | O41: 46026 | P41: 0.4575
B42: -1 | C42: B4 | D42: 4 | E42: SX | F42: LinRespSpec | G42: Max | H42: 0.915 | I42: 0 | J42: 0.1101 | K42: 0 | L42: 0 | M42: 0 | N42: 0.1008 | O42: 46026 | P42: 0.915
B43: -1 | C43: B4 | D43: 4 | E43: SX | F43: LinRespSpec | G43: Max | H43: 0.915 | I43: 0 | J43: 0.0216 | K43: 0 | L43: 0 | M43: 0 | N43: 0.084 | O43: 46057 | P43: 0
B44: -1 | C44: B4 | D44: 4 | E44: SX | F44: LinRespSpec | G44: Max | H44: 1.3725 | I44: 0 | J44: 0.0216 | K44: 0 | L44: 0 | M44: 0 | N44: 0.0741 | O44: 46057 | P44: 0.4575
B45: -1 | C45: B4 | D45: 4 | E45: SX | F45: LinRespSpec | G45: Max | H45: 1.83 | I45: 0 | J45: 0.0216 | K45: 0 | L45: 0 | M45: 0 | N45: 0.0643 | O45: 46057 | P45: 0.915
B46: -1 | C46: B4 | D46: 4 | E46: SX | F46: LinRespSpec | G46: Max | H46: 1.83 | I46: 0 | J46: 0.035 | K46: 0 | L46: 0 | M46: 0 | N46: 0.0633 | O46: 46085 | P46: 0
B47: -1 | C47: B4 | D47: 4 | E47: SX | F47: LinRespSpec | G47: Max | H47: 2.2875 | I47: 0 | J47: 0.035 | K47: 0 | L47: 0 | M47: 0 | N47: 0.0473 | O47: 46085 | P47: 0.4575
B48: -1 | C48: B4 | D48: 4 | E48: SX | F48: LinRespSpec | G48: Max | H48: 2.745 | I48: 0 | J48: 0.035 | K48: 0 | L48: 0 | M48: 0 | N48: 0.0313 | O48: 46085 | P48: 0.915
B49: -1 | C49: B4 | D49: 4 | E49: SX | F49: LinRespSpec | G49: Max | H49: 2.745 | I49: 0 | J49: 0.0394 | K49: 0 | L49: 0 | M49: 0 | N49: 0.0299 | O49: 46116 | P49: 0
B50: -1 | C50: B4 | D50: 4 | E50: SX | F50: LinRespSpec | G50: Max | H50: 3.2025 | I50: 0 | J50: 0.0394 | K50: 0 | L50: 0 | M50: 0 | N50: 0.012 | O50: 46116 | P50: 0.4575
B51: -1 | C51: B4 | D51: 4 | E51: SX | F51: LinRespSpec | G51: Max | H51: 3.66 | I51: 0 | J51: 0.0394 | K51: 0 | L51: 0 | M51: 0 | N51: 0.0065 | O51: 46116 | P51: 0.915
... B75: -1 | C75: B4 | D75: 4 | E75: SY | F75: LinRespSpec | G75: Max | H75: 5.34 | I75: 0 | J75: 0.0073 | K75: 0 | L75: 0 | M75: 0 | N75: 0.0099 | O75: 46177 | P75: 0.765
B76: -1 | C76: B4 | D76: 4 | E76: C1 | F76: Combination | H76: 0 | I76: 0 | J76: -1.3933 | K76: 0 | L76: 0 | M76: 0 | N76: 0 | O76: 46026 | P76: 0
B77: -1 | C77: B4 | D77: 4 | E77: C1 | F77: Combination | H77: 0.4575 | I77: 0 | J77: -1.1932 | K77: 0 | L77: 0 | M77: 0 | N77: 0.5917 | O77: 46026 | P77: 0.4575
B78: -1 | C78: B4 | D78: 4 | E78: C1 | F78: Combination | H78: 0.915 | I78: 0 | J78: -0.993 | K78: 0 | L78: 0 | M78: 0 | N78: 1.0918 | O78: 46026 | P78: 0.915
B79: -1 | C79: B4 | D79: 4 | E79: C1 | F79: Combination | H79: 0.915 | I79: 0 | J79: -2.3 | K79: 0 | L79: 0 | M79: 0 | N79: 1.4182 | O79: 46057 | P79: 0
B80: -1 | C80: B4 | D80: 4 | E80: C1 | F80: Combination | H80: 1.3725 | I80: 0 | J80: -2.0998 | K80: 0 | L80: 0 | M80: 0 | N80: 2.4246 | O80: 46057 | P80: 0.4575
B81: -1 | C81: B4 | D81: 4 | E81: C1 | F81: Combination | H81: 1.83 | I81: 0 | J81: -1.8997 | K81: 0 | L81: 0 | M81: 0 | N81: 3.3395 | O81: 46057 | P81: 0.915
B82: -1 | C82: B4 | D82: 4 | E82: C1 | F82: Combination | H82: 1.83 | I82: 0 | J82: -0.5554 | K82: 0 | L82: 0 | M82: 0 | N82: 3.3826 | O82: 46085 | P82: 0
B83: -1 | C83: B4 | D83: 4 | E83: C1 | F83: Combination | H83: 2.2875 | I83: 0 | J83: -0.3553 | K83: 0 | L83: 0 | M83: 0 | N83: 3.5909 | O83: 46085 | P83: 0.4575
B84: -1 | C84: B4 | D84: 4 | E84: C1 | F84: Combination | H84: 2.745 | I84: 0 | J84: -0.1551 | K84: 0 | L84: 0 | M84: 0 | N84: 3.7077 | O84: 46085 | P84: 0.915
B85: -1 | C85: B4 | D85: 4 | E85: C1 | F85: Combination | H85: 2.745 | I85: 0 | J85: 1.5512 | K85: 0 | L85: 0 | M85: 0 | N85: 3.68 | O85: 46116 | P85: 0
B86: -1 | C86: B4 | D86: 4 | E86: C1 | F86: Combination | H86: 3.2025 | I86: 0 | J86: 1.7513 | K86: 0 | L86: 0 | M86: 0 | N86: 2.9245 | O86: 46116 | P86: 0.4575
B87: -1 | C87: B4 | D87: 4 | E87: C1 | F87: Combination | H87: 3.66 | I87: 0 | J87: 1.9515 | K87: 0 | L87: 0 | M87: 0 | N87: 2.0775 | O87: 46116 | P87: 0.915
...

Sheet B4
B2: Story | C2: Beam | D2: Unique Name | E2: Output Case | F2: Case Type | G2: Step Type | H2: Station | I2: P | J2: V2 | K2: V3 | L2: T | M2: M2 | N2: M3 | O2: Element | P2: Elem Station | Q2: Location
H3: m | I3: tonf | J3: tonf | K3: tonf | L3: tonf-m | M3: tonf-m | N3: tonf-m | P3: m
B4: ='Set a analizar'!B4 -> -1 | C4: ='Set a analizar'!C4 -> B4 | D4: ='Set a analizar'!D4 -> 4 | E4: ='Set a analizar'!E4 -> PP | F4: ='Set a analizar'!F4 -> LinStatic | G4: ='Set a analizar'!G4 -> 0 | H4: ='Set a analizar'!H4 -> 0 | I4: ='Set a analizar'!I4 -> 0 | ... Q4: ='Set a analizar'!Q4 -> 0 | S4: Mmax | T4: =MAX(N4:N309) -> 7.1124 | U4: tonfm | X4: Ni | Y4: Ni+1
B5: ='Set a analizar'!B5 -> -1 | C5: ='Set a analizar'!C5 -> B4 | D5: ='Set a analizar'!D5 -> 4 | E5: ='Set a analizar'!E5 -> PP | F5: ='Set a analizar'!F5 -> LinStatic | G5: ='Set a analizar'!G5 -> 0 | H5: ='Set a analizar'!H5 -> 0.4575 | I5: ='Set a analizar'!I5 -> 0 | ... Q5: ='Set a analizar'!Q5 -> 0 | S5: Mmin | T5: =MIN(N4:N309) -> -11.0976 | U5: tonfm | X5: rot | Y5: emp | AA5: fc | AB5: =T18 -> 35 | AC5: 0.85
B6: ='Set a analizar'!B6 -> -1 | C6: ='Set a analizar'!C6 -> B4 | D6: ='Set a analizar'!D6 -> 4 | E6: ='Set a analizar'!E6 -> PP | F6: ='Set a analizar'!F6 -> LinStatic | G6: ='Set a analizar'!G6 -> 0 | H6: ='Set a analizar'!H6 -> 0.915 | I6: ='Set a analizar'!I6 -> 0 | ... Q6: ='Set a analizar'!Q6 -> 0 | X6: 4.4 | Y6: 9.89 | AC6: 0.65
B7: ='Set a analizar'!B7 -> -1 | C7: ='Set a analizar'!C7 -> B4 | D7: ='Set a analizar'!D7 -> 4 | E7: ='Set a analizar'!E7 -> PP | F7: ='Set a analizar'!F7 -> LinStatic | G7: ='Set a analizar'!G7 -> 0 | H7: ='Set a analizar'!H7 -> 0.915 | I7: ='Set a analizar'!I7 -> 0 | ... Q7: ='Set a analizar'!Q7 -> 0 | S7: Vmax | T7: =MAX(J4:J309) -> 10.6535 | U7: tonf | AC7: =0.85-(0.05*(AB5-28)/7) -> 0.8
B8: ='Set a analizar'!B8 -> -1 | C8: ='Set a analizar'!C8 -> B4 | D8: ='Set a analizar'!D8 -> 4 | E8: ='Set a analizar'!E8 -> PP | F8: ='Set a analizar'!F8 -> LinStatic | G8: ='Set a analizar'!G8 -> 0 | H8: ='Set a analizar'!H8 -> 1.3725 | I8: ='Set a analizar'!I8 -> 0 | ... Q8: ='Set a analizar'!Q8 -> 0 | S8: Vmin | T8: =MIN(J4:J309) -> -4.3169 | U8: tonf
B9: ='Set a analizar'!B9 -> -1 | C9: ='Set a analizar'!C9 -> B4 | D9: ='Set a analizar'!D9 -> 4 | E9: ='Set a analizar'!E9 -> PP | F9: ='Set a analizar'!F9 -> LinStatic | G9: ='Set a analizar'!G9 -> 0 | H9: ='Set a analizar'!H9 -> 1.83 | I9: ='Set a analizar'!I9 -> 0 | ... Q9: ='Set a analizar'!Q9 -> 0 | Y9: Flexión | AD9: Corte
B10: ='Set a analizar'!B10 -> -1 | C10: ='Set a analizar'!C10 -> B4 | D10: ='Set a analizar'!D10 -> 4 | E10: ='Set a analizar'!E10 -> PP | F10: ='Set a analizar'!F10 -> LinStatic | G10: ='Set a analizar'!G10 -> 0 | H10: ='Set a analizar'!H10 -> 1.83 | I10: ='Set a analizar'!I10 -> 0 | ... Q10: ='Set a analizar'!Q10 -> 0 | S10: Geometría del perfil | Y10: Diámetro | Z10: Área | AA10: Unidades | AB10: Área total | AD10: Diámetro | AE10: Área | AF10: Unidades | AG10: Área total
B11: ='Set a analizar'!B11 -> -1 | C11: ='Set a analizar'!C11 -> B4 | D11: ='Set a analizar'!D11 -> 4 | E11: ='Set a analizar'!E11 -> PP | F11: ='Set a analizar'!F11 -> LinStatic | G11: ='Set a analizar'!G11 -> 0 | H11: ='Set a analizar'!H11 -> 2.2875 | I11: ='Set a analizar'!I11 -> 0 | ... Q11: ='Set a analizar'!Q11 -> 0 | S11: h | T11: 0.5 | U11: m | Y11: mm | Z11: mm^2 | AB11: mm^2 | AD11: mm | AE11: mm^2 | AG11: mm^2
B12: ='Set a analizar'!B12 -> -1 | C12: ='Set a analizar'!C12 -> B4 | D12: ='Set a analizar'!D12 -> 4 | E12: ='Set a analizar'!E12 -> PP | F12: ='Set a analizar'!F12 -> LinStatic | G12: ='Set a analizar'!G12 -> 0 | H12: ='Set a analizar'!H12 -> 2.745 | I12: ='Set a analizar'!I12 -> 0 | ... Q12: ='Set a analizar'!Q12 -> 0 | S12: b | T12: 0.25 | U12: m | Y12: 8 | Z12: =PI()*(Y12/2)^2 -> 50.265482 | AB12: =AA12*Z12 -> 0 | AD12: 8 | AE12: =PI()*(AD12/2)^2 -> 50.265482 | AF12: 1 | AG12: =AF12*AE12 -> 50.265482
B13: ='Set a analizar'!B13 -> -1 | C13: ='Set a analizar'!C13 -> B4 | D13: ='Set a analizar'!D13 -> 4 | E13: ='Set a analizar'!E13 -> PP | F13: ='Set a analizar'!F13 -> LinStatic | G13: ='Set a analizar'!G13 -> 0 | H13: ='Set a analizar'!H13 -> 2.745 | I13: ='Set a analizar'!I13 -> 0 | ... Q13: ='Set a analizar'!Q13 -> 0 | S13: rec | T13: 5 | U13: cm | Y13: 10 | Z13: =PI()*(Y13/2)^2 -> 78.539816 | AB13: =AA13*Z13 -> 0 | AD13: 10 | AE13: =PI()*(AD13/2)^2 -> 78.539816 | AG13: =AF13*AE13 -> 0
B14: ='Set a analizar'!B14 -> -1 | C14: ='Set a analizar'!C14 -> B4 | D14: ='Set a analizar'!D14 -> 4 | E14: ='Set a analizar'!E14 -> PP | F14: ='Set a analizar'!F14 -> LinStatic | G14: ='Set a analizar'!G14 -> 0 | H14: ='Set a analizar'!H14 -> 3.2025 | I14: ='Set a analizar'!I14 -> 0 | ... Q14: ='Set a analizar'!Q14 -> 0 | S14: d | T14: =T11-T13/100 -> 0.45 | U14: m | Y14: 12 | Z14: =PI()*(Y14/2)^2 -> 113.09734 | AB14: =AA14*Z14 -> 0 | AD14: 12 | AE14: =PI()*(AD14/2)^2 -> 113.09734 | AG14: =AF14*AE14 -> 0
B15: ='Set a analizar'!B15 -> -1 | C15: ='Set a analizar'!C15 -> B4 | D15: ='Set a analizar'!D15 -> 4 | E15: ='Set a analizar'!E15 -> PP | F15: ='Set a analizar'!F15 -> LinStatic | G15: ='Set a analizar'!G15 -> 0 | H15: ='Set a analizar'!H15 -> 3.66 | I15: ='Set a analizar'!I15 -> 0 | ... Q15: ='Set a analizar'!Q15 -> 0 | Y15: 16 | Z15: =PI()*(Y15/2)^2 -> 201.06193 | AB15: =AA15*Z15 -> 0 | AD15: 16 | AE15: =PI()*(AD15/2)^2 -> 201.06193 | AG15: =AF15*AE15 -> 0
B16: ='Set a analizar'!B16 -> -1 | C16: ='Set a analizar'!C16 -> B4 | D16: ='Set a analizar'!D16 -> 4 | E16: ='Set a analizar'!E16 -> PP | F16: ='Set a analizar'!F16 -> LinStatic | G16: ='Set a analizar'!G16 -> 0 | H16: ='Set a analizar'!H16 -> 3.66 | I16: ='Set a analizar'!I16 -> 0 | ... Q16: ='Set a analizar'!Q16 -> 0 | S16: Características | Y16: 18 | Z16: =PI()*(Y16/2)^2 -> 254.469 | AA16: 3 | AB16: =AA16*Z16 -> 763.40701 | AD16: 18 | AE16: =PI()*(AD16/2)^2 -> 254.469 | AF16: 0 | AG16: =AF16*AE16 -> 0
B17: ='Set a analizar'!B17 -> -1 | C17: ='Set a analizar'!C17 -> B4 | D17: ='Set a analizar'!D17 -> 4 | E17: ='Set a analizar'!E17 -> PP | F17: ='Set a analizar'!F17 -> LinStatic | G17: ='Set a analizar'!G17 -> 0 | H17: ='Set a analizar'!H17 -> 4.1175 | I17: ='Set a analizar'!I17 -> 0 | ... Q17: ='Set a analizar'!Q17 -> 0 | S17: L | T17: =Y6-X6 -> 5.49 | U17: m | Y17: 22 | Z17: =PI()*(Y17/2)^2 -> 380.13271 | AA17: 0 | AB17: =AA17*Z17 -> 0 | AD17: 22 | AE17: =PI()*(AD17/2)^2 -> 380.13271 | AF17: 0 | AG17: =AF17*AE17 -> 0
B18: ='Set a analizar'!B18 -> -1 | C18: ='Set a analizar'!C18 -> B4 | D18: ='Set a analizar'!D18 -> 4 | E18: ='Set a analizar'!E18 -> PP | F18: ='Set a analizar'!F18 -> LinStatic | G18: ='Set a analizar'!G18 -> 0 | H18: ='Set a analizar'!H18 -> 4.575 | I18: ='Set a analizar'!I18 -> 0 | ... Q18: ='Set a analizar'!Q18 -> 0 | S18: f'c | T18: 35 | U18: Mpa | Y18: 25 | Z18: =PI()*(Y18/2)^2 -> 490.87385 | AB18: =AA18*Z18 -> 0 | AD18: 25 | AE18: =PI()*(AD18/2)^2 -> 490.87385 | AG18: =AF18*AE18 -> 0
B19: ='Set a analizar'!B19 -> -1 | C19: ='Set a analizar'!C19 -> B4 | D19: ='Set a analizar'!D19 -> 4 | E19: ='Set a analizar'!E19 -> PP | F19: ='Set a analizar'!F19 -> LinStatic | G19: ='Set a analizar'!G19 -> 0 | H19: ='Set a analizar'!H19 -> 4.575 | I19: ='Set a analizar'!I19 -> 0 | ... Q19: ='Set a analizar'!Q19 -> 0 | S19: E | T19: =4700*(SQRT(T18))/1000 -> 27.805575 | U19: Gpa | Y19: 28 | Z19: =PI()*(Y19/2)^2 -> 615.75216 | AB19: =AA19*Z19 -> 0 | AD19: 28 | AE19: =PI()*(AD19/2)^2 -> 615.75216 | AG19: =AF19*AE19 -> 0
B20: ='Set a analizar'!B20 -> -1 | C20: ='Set a analizar'!C20 -> B4 | D20: ='Set a analizar'!D20 -> 4 | E20: ='Set a analizar'!E20 -> PP | F20: ='Set a analizar'!F20 -> LinStatic | G20: ='Set a analizar'!G20 -> 0 | H20: ='Set a analizar'!H20 -> 4.9575 | I20: ='Set a analizar'!I20 -> 0 | ... Q20: ='Set a analizar'!Q20 -> 0 | S20: f'c | T20: =T18*9.81*10 -> 3433.5 | U20: tonf/m^2 | Y20: 32 | Z20: =PI()*(Y20/2)^2 -> 804.24772 | AB20: =AA20*Z20 -> 0 | AD20: 32 | AE20: =PI()*(AD20/2)^2 -> 804.24772 | AG20: =AF20*AE20 -> 0
B21: ='Set a analizar'!B21 -> -1 | C21: ='Set a analizar'!C21 -> B4 | D21: ='Set a analizar'!D21 -> 4 | E21: ='Set a analizar'!E21 -> PP | F21: ='Set a analizar'!F21 -> LinStatic | G21: ='Set a analizar'!G21 -> 0 | H21: ='Set a analizar'!H21 -> 5.34 | I21: ='Set a analizar'!I21 -> 0 | ... Q21: ='Set a analizar'!Q21 -> 0 | S21: E | T21: =151*((T20/10)^0.5)/1000*(1000*1000) -> 2797985.6 | U21: tonf/m^2 | Y21: 36 | Z21: =PI()*(Y21/2)^2 -> 1017.876 | AB21: =AA21*Z21 -> 0 | AD21: 36 | AE21: =PI()*(AD21/2)^2 -> 1017.876 | AG21: =AF21*AE21 -> 0
B22: ='Set a analizar'!B22 -> -1 | C22: ='Set a analizar'!C22 -> B4 | D22: ='Set a analizar'!D22 -> 4 | E22: ='Set a analizar'!E22 -> SC | F22: ='Set a analizar'!F22 -> LinStatic | G22: ='Set a analizar'!G22 -> 0 | H22: ='Set a analizar'!H22 -> 0 | I22: ='Set a analizar'!I22 -> 0 | ... Q22: ='Set a analizar'!Q22 -> 0 | S22: I | T22: =((T11^3)*(T12))/12 -> 0.0026041667 | U22: m^4 | Y22: 40 | Z22: =PI()*(Y22/2)^2 -> 1256.6371 | AB22: =AA22*Z22 -> 0 | AD22: 40 | AE22: =PI()*(AD22/2)^2 -> 1256.6371 | AG22: =AF22*AE22 -> 0
B23: ='Set a analizar'!B23 -> -1 | C23: ='Set a analizar'!C23 -> B4 | D23: ='Set a analizar'!D23 -> 4 | E23: ='Set a analizar'!E23 -> SC | F23: ='Set a analizar'!F23 -> LinStatic | G23: ='Set a analizar'!G23 -> 0 | H23: ='Set a analizar'!H23 -> 0.4575 | I23: ='Set a analizar'!I23 -> 0 | ... Q23: ='Set a analizar'!Q23 -> 0 | S23: fy | T23: 420 | U23: MPa
B24: ='Set a analizar'!B24 -> -1 | C24: ='Set a analizar'!C24 -> B4 | D24: ='Set a analizar'!D24 -> 4 | E24: ='Set a analizar'!E24 -> SC | F24: ='Set a analizar'!F24 -> LinStatic | G24: ='Set a analizar'!G24 -> 0 | H24: ='Set a analizar'!H24 -> 0.915 | I24: ='Set a analizar'!I24 -> 0 | ... Q24: ='Set a analizar'!Q24 -> 0 | S24: fy | T24: =T23*98.1 -> 41202 | U24: tonf/m^2 | Y24: Área máxima | AB24: =T46*1000*1000 -> 2390.625 | AC24: mm^2
B25: ='Set a analizar'!B25 -> -1 | C25: ='Set a analizar'!C25 -> B4 | D25: ='Set a analizar'!D25 -> 4 | E25: ='Set a analizar'!E25 -> SC | F25: ='Set a analizar'!F25 -> LinStatic | G25: ='Set a analizar'!G25 -> 0 | H25: ='Set a analizar'!H25 -> 0.915 | I25: ='Set a analizar'!I25 -> 0 | ... Q25: ='Set a analizar'!Q25 -> 0 | S25: e_c | T25: 0.003 | Y25: Área mínima | AB25: =T39*10*10 -> 375 | AC25: mm^2
B26: ='Set a analizar'!B26 -> -1 | C26: ='Set a analizar'!C26 -> B4 | D26: ='Set a analizar'!D26 -> 4 | E26: ='Set a analizar'!E26 -> SC | F26: ='Set a analizar'!F26 -> LinStatic | G26: ='Set a analizar'!G26 -> 0 | H26: ='Set a analizar'!H26 -> 1.3725 | I26: ='Set a analizar'!I26 -> 0 | ... Q26: ='Set a analizar'!Q26 -> 0 | S26: e_y | T26: 0.002 | Y26: Área | AB26: =SUM(AB12:AB22) -> 763.40701 | AD26: Área | AG26: =SUM(AG12:AG22) -> 50.265482
B27: ='Set a analizar'!B27 -> -1 | C27: ='Set a analizar'!C27 -> B4 | D27: ='Set a analizar'!D27 -> 4 | E27: ='Set a analizar'!E27 -> SC | F27: ='Set a analizar'!F27 -> LinStatic | G27: ='Set a analizar'!G27 -> 0 | H27: ='Set a analizar'!H27 -> 1.83 | I27: ='Set a analizar'!I27 -> 0 | ... Q27: ='Set a analizar'!Q27 -> 0 | S27: A_g | T27: =T11*T12 -> 0.125 | U27: m^2 | Y27: check | AB27: =IF(AND(AB25<AB26,AB26<AB24),"Estas bien","tay fuera") -> Estas bien
B28: ='Set a analizar'!B28 -> -1 | C28: ='Set a analizar'!C28 -> B4 | D28: ='Set a analizar'!D28 -> 4 | E28: ='Set a analizar'!E28 -> SC | F28: ='Set a analizar'!F28 -> LinStatic | G28: ='Set a analizar'!G28 -> 0 | H28: ='Set a analizar'!H28 -> 1.83 | I28: ='Set a analizar'!I28 -> 0 | ... Q28: ='Set a analizar'!Q28 -> 0
B29: ='Set a analizar'!B29 -> -1 | C29: ='Set a analizar'!C29 -> B4 | D29: ='Set a analizar'!D29 -> 4 | E29: ='Set a analizar'!E29 -> SC | F29: ='Set a analizar'!F29 -> LinStatic | G29: ='Set a analizar'!G29 -> 0 | H29: ='Set a analizar'!H29 -> 2.2875 | I29: ='Set a analizar'!I29 -> 0 | ... Q29: ='Set a analizar'!Q29 -> 0
B30: ='Set a analizar'!B30 -> -1 | C30: ='Set a analizar'!C30 -> B4 | D30: ='Set a analizar'!D30 -> 4 | E30: ='Set a analizar'!E30 -> SC | F30: ='Set a analizar'!F30 -> LinStatic | G30: ='Set a analizar'!G30 -> 0 | H30: ='Set a analizar'!H30 -> 2.745 | I30: ='Set a analizar'!I30 -> 0 | ... Q30: ='Set a analizar'!Q30 -> 0 | S30: Cálculo de flexión | W30: Cálculo de corte
B31: ='Set a analizar'!B31 -> -1 | C31: ='Set a analizar'!C31 -> B4 | D31: ='Set a analizar'!D31 -> 4 | E31: ='Set a analizar'!E31 -> SC | F31: ='Set a analizar'!F31 -> LinStatic | G31: ='Set a analizar'!G31 -> 0 | H31: ='Set a analizar'!H31 -> 2.745 | I31: ='Set a analizar'!I31 -> 0 | ... Q31: ='Set a analizar'!Q31 -> 0
B32: ='Set a analizar'!B32 -> -1 | C32: ='Set a analizar'!C32 -> B4 | D32: ='Set a analizar'!D32 -> 4 | E32: ='Set a analizar'!E32 -> SC | F32: ='Set a analizar'!F32 -> LinStatic | G32: ='Set a analizar'!G32 -> 0 | H32: ='Set a analizar'!H32 -> 3.2025 | I32: ='Set a analizar'!I32 -> 0 | ... Q32: ='Set a analizar'!Q32 -> 0
B33: ='Set a analizar'!B33 -> -1 | C33: ='Set a analizar'!C33 -> B4 | D33: ='Set a analizar'!D33 -> 4 | E33: ='Set a analizar'!E33 -> SC | F33: ='Set a analizar'!F33 -> LinStatic | G33: ='Set a analizar'!G33 -> 0 | H33: ='Set a analizar'!H33 -> 3.66 | I33: ='Set a analizar'!I33 -> 0 | ... Q33: ='Set a analizar'!Q33 -> 0
B34: ='Set a analizar'!B34 -> -1 | C34: ='Set a analizar'!C34 -> B4 | D34: ='Set a analizar'!D34 -> 4 | E34: ='Set a analizar'!E34 -> SC | F34: ='Set a analizar'!F34 -> LinStatic | G34: ='Set a analizar'!G34 -> 0 | H34: ='Set a analizar'!H34 -> 3.66 | I34: ='Set a analizar'!I34 -> 0 | ... Q34: ='Set a analizar'!Q34 -> 0
B35: ='Set a analizar'!B35 -> -1 | C35: ='Set a analizar'!C35 -> B4 | D35: ='Set a analizar'!D35 -> 4 | E35: ='Set a analizar'!E35 -> SC | F35: ='Set a analizar'!F35 -> LinStatic | G35: ='Set a analizar'!G35 -> 0 | H35: ='Set a analizar'!H35 -> 4.1175 | I35: ='Set a analizar'!I35 -> 0 | ... Q35: ='Set a analizar'!Q35 -> 0 | S35: Parámetros importantes | W35: Resistencia del hormigón al corte
B36: ='Set a analizar'!B36 -> -1 | C36: ='Set a analizar'!C36 -> B4 | D36: ='Set a analizar'!D36 -> 4 | E36: ='Set a analizar'!E36 -> SC | F36: ='Set a analizar'!F36 -> LinStatic | G36: ='Set a analizar'!G36 -> 0 | H36: ='Set a analizar'!H36 -> 4.575 | I36: ='Set a analizar'!I36 -> 0 | ... Q36: ='Set a analizar'!Q36 -> 0 | S36: Enfierradura mínima | W36: V_u | X36: =T7*9.81 -> 104.51084 | Y36: kN
B37: ='Set a analizar'!B37 -> -1 | C37: ='Set a analizar'!C37 -> B4 | D37: ='Set a analizar'!D37 -> 4 | E37: ='Set a analizar'!E37 -> SC | F37: ='Set a analizar'!F37 -> LinStatic | G37: ='Set a analizar'!G37 -> 0 | H37: ='Set a analizar'!H37 -> 4.575 | I37: ='Set a analizar'!I37 -> 0 | ... Q37: ='Set a analizar'!Q37 -> 0 | S37: As_min1 | T37: =(0.25*SQRT(T18))/T23*T11*T12*100*100 -> 4.4018451 | U37: cm^2 | W37: V_c | X37: =0.17*1*SQRT(T18)*T12*T14*1000*1000/1000 -> 113.14503 | Y37: kN
B38: ='Set a analizar'!B38 -> -1 | C38: ='Set a analizar'!C38 -> B4 | D38: ='Set a analizar'!D38 -> 4 | E38: ='Set a analizar'!E38 -> SC | F38: ='Set a analizar'!F38 -> LinStatic | G38: ='Set a analizar'!G38 -> 0 | H38: ='Set a analizar'!H38 -> 4.9575 | I38: ='Set a analizar'!I38 -> 0 | ... Q38: ='Set a analizar'!Q38 -> 0 | S38: As_min2 | T38: =1.4*T14*T12/T23*100*100 -> 3.75 | U38: cm^2 | W38: Factor | X38: =0.75*(X37+0.66*SQRT(T18)*T12*T14*1000) -> 414.31046 | Y38: kN
B39: ='Set a analizar'!B39 -> -1 | C39: ='Set a analizar'!C39 -> B4 | D39: ='Set a analizar'!D39 -> 4 | E39: ='Set a analizar'!E39 -> SC | F39: ='Set a analizar'!F39 -> LinStatic | G39: ='Set a analizar'!G39 -> 0 | H39: ='Set a analizar'!H39 -> 5.34 | I39: ='Set a analizar'!I39 -> 0 | ... Q39: ='Set a analizar'!Q39 -> 0 | S39: As_min | T39: =MIN(T37:T38) -> 3.75 | U39: cm^2
B40: ='Set a analizar'!B40 -> -1 | C40: ='Set a analizar'!C40 -> B4 | D40: ='Set a analizar'!D40 -> 4 | E40: ='Set a analizar'!E40 -> SX | F40: ='Set a analizar'!F40 -> LinRespSpec | G40: ='Set a analizar'!G40 -> Max | H40: ='Set a analizar'!H40 -> 0 | I40: ='Set a analizar'!I40 -> 0 | ... Q40: ='Set a analizar'!Q40 -> 0 | S40: rho_min | T40: =T39/(T12*100*T14*100) -> 0.0033333333 | W40: Se requiere armadura?
B41: ='Set a analizar'!B41 -> -1 | C41: ='Set a analizar'!C41 -> B4 | D41: ='Set a analizar'!D41 -> 4 | E41: ='Set a analizar'!E41 -> SX | F41: ='Set a analizar'!F41 -> LinRespSpec | G41: ='Set a analizar'!G41 -> Max | H41: ='Set a analizar'!H41 -> 0.4575 | I41: ='Set a analizar'!I41 -> 0 | ... Q41: ='Set a analizar'!Q41 -> 0 | W41: 0.9*V_c/2 | X41: =0.75*X37/2 -> 42.429385
...

Sheet B8
B2: Story | C2: Beam | D2: Unique Name | E2: Output Case | F2: Case Type | G2: Step Type | H2: Station | I2: P | J2: V2 | K2: V3 | L2: T | M2: M2 | N2: M3 | O2: Element | P2: Elem Station | Q2: Location
H3: m | I3: tonf | J3: tonf | K3: tonf | L3: tonf-m | M3: tonf-m | N3: tonf-m | P3: m
B4: ='Set a analizar'!B310 -> -1 | C4: ='Set a analizar'!C310 -> B8 | D4: ='Set a analizar'!D310 -> 8 | E4: ='Set a analizar'!E310 -> PP | F4: ='Set a analizar'!F310 -> LinStatic | G4: ='Set a analizar'!G310 -> 0 | H4: ='Set a analizar'!H310 -> 0.15 | I4: ='Set a analizar'!I310 -> 0 | ... Q4: ='Set a analizar'!Q310 -> 0 | S4: Mmax | T4: =MAX(N4:N309) -> 7.0797 | U4: tonfm
B5: ='Set a analizar'!B311 -> -1 | C5: ='Set a analizar'!C311 -> B8 | D5: ='Set a analizar'!D311 -> 8 | E5: ='Set a analizar'!E311 -> PP | F5: ='Set a analizar'!F311 -> LinStatic | G5: ='Set a analizar'!G311 -> 0 | H5: ='Set a analizar'!H311 -> 0.555 | I5: ='Set a analizar'!I311 -> 0 | ... Q5: ='Set a analizar'!Q311 -> 0 | S5: Mmin | T5: =MIN(N4:N309) -> -11.0742 | U5: tonfm | AA5: fc | AB5: =T18 -> 35 | AC5: 0.85
B6: ='Set a analizar'!B312 -> -1 | C6: ='Set a analizar'!C312 -> B8 | D6: ='Set a analizar'!D312 -> 8 | E6: ='Set a analizar'!E312 -> PP | F6: ='Set a analizar'!F312 -> LinStatic | G6: ='Set a analizar'!G312 -> 0 | H6: ='Set a analizar'!H312 -> 0.96 | I6: ='Set a analizar'!I312 -> 0 | ... Q6: ='Set a analizar'!Q312 -> 0 | AC6: 0.65
B7: ='Set a analizar'!B313 -> -1 | C7: ='Set a analizar'!C313 -> B8 | D7: ='Set a analizar'!D313 -> 8 | E7: ='Set a analizar'!E313 -> PP | F7: ='Set a analizar'!F313 -> LinStatic | G7: ='Set a analizar'!G313 -> 0 | H7: ='Set a analizar'!H313 -> 0.96 | I7: ='Set a analizar'!I313 -> 0 | ... Q7: ='Set a analizar'!Q313 -> 0 | S7: Vmax | T7: =MAX(J4:J309) -> 10.2554 | U7: tonf | AC7: =0.85-(0.05*(AB5-28)/7) -> 0.8
B8: ='Set a analizar'!B314 -> -1 | C8: ='Set a analizar'!C314 -> B8 | D8: ='Set a analizar'!D314 -> 8 | E8: ='Set a analizar'!E314 -> PP | F8: ='Set a analizar'!F314 -> LinStatic | G8: ='Set a analizar'!G314 -> 0 | H8: ='Set a analizar'!H314 -> 1.459 | I8: ='Set a analizar'!I314 -> 0 | ... Q8: ='Set a analizar'!Q314 -> 0 | S8: Vmin | T8: =MIN(J4:J309) -> -10.4822 | U8: tonf
B9: ='Set a analizar'!B315 -> -1 | C9: ='Set a analizar'!C315 -> B8 | D9: ='Set a analizar'!D315 -> 8 | E9: ='Set a analizar'!E315 -> PP | F9: ='Set a analizar'!F315 -> LinStatic | G9: ='Set a analizar'!G315 -> 0 | H9: ='Set a analizar'!H315 -> 1.958 | I9: ='Set a analizar'!I315 -> 0 | ... Q9: ='Set a analizar'!Q315 -> 0 | Y9: Flexión | AD9: Corte
B10: ='Set a analizar'!B316 -> -1 | C10: ='Set a analizar'!C316 -> B8 | D10: ='Set a analizar'!D316 -> 8 | E10: ='Set a analizar'!E316 -> PP | F10: ='Set a analizar'!F316 -> LinStatic | G10: ='Set a analizar'!G316 -> 0 | H10: ='Set a analizar'!H316 -> 1.958 | I10: ='Set a analizar'!I316 -> 0 | ... Q10: ='Set a analizar'!Q316 -> 0 | S10: Geometría del perfil | Y10: Diámetro | Z10: Área | AA10: Unidades | AB10: Área total | AD10: Diámetro | AE10: Área | AF10: Unidades | AG10: Área total
B11: ='Set a analizar'!B317 -> -1 | C11: ='Set a analizar'!C317 -> B8 | D11: ='Set a analizar'!D317 -> 8 | E11: ='Set a analizar'!E317 -> PP | F11: ='Set a analizar'!F317 -> LinStatic | G11: ='Set a analizar'!G317 -> 0 | H11: ='Set a analizar'!H317 -> 2.457 | I11: ='Set a analizar'!I317 -> 0 | ... Q11: ='Set a analizar'!Q317 -> 0 | S11: h | T11: 0.5 | U11: m | Y11: mm | Z11: mm^2 | AB11: mm^2 | AD11: mm | AE11: mm^2 | AG11: mm^2
B12: ='Set a analizar'!B318 -> -1 | C12: ='Set a analizar'!C318 -> B8 | D12: ='Set a analizar'!D318 -> 8 | E12: ='Set a analizar'!E318 -> PP | F12: ='Set a analizar'!F318 -> LinStatic | G12: ='Set a analizar'!G318 -> 0 | H12: ='Set a analizar'!H318 -> 2.956 | I12: ='Set a analizar'!I318 -> 0 | ... Q12: ='Set a analizar'!Q318 -> 0 | S12: b | T12: 0.25 | U12: m | Y12: 8 | Z12: =PI()*(Y12/2)^2 -> 50.265482 | AB12: =AA12*Z12 -> 0 | AD12: 8 | AE12: =PI()*(AD12/2)^2 -> 50.265482 | AF12: 1 | AG12: =AF12*AE12 -> 50.265482
B13: ='Set a analizar'!B319 -> -1 | C13: ='Set a analizar'!C319 -> B8 | D13: ='Set a analizar'!D319 -> 8 | E13: ='Set a analizar'!E319 -> PP | F13: ='Set a analizar'!F319 -> LinStatic | G13: ='Set a analizar'!G319 -> 0 | H13: ='Set a analizar'!H319 -> 2.956 | I13: ='Set a analizar'!I319 -> 0 | ... Q13: ='Set a analizar'!Q319 -> 0 | S13: rec | T13: 5 | U13: cm | Y13: 10 | Z13: =PI()*(Y13/2)^2 -> 78.539816 | AB13: =AA13*Z13 -> 0 | AD13: 10 | AE13: =PI()*(AD13/2)^2 -> 78.539816 | AG13: =AF13*AE13 -> 0
B14: ='Set a analizar'!B320 -> -1 | C14: ='Set a analizar'!C320 -> B8 | D14: ='Set a analizar'!D320 -> 8 | E14: ='Set a analizar'!E320 -> PP | F14: ='Set a analizar'!F320 -> LinStatic | G14: ='Set a analizar'!G320 -> 0 | H14: ='Set a analizar'!H320 -> 3.455 | I14: ='Set a analizar'!I320 -> 0 | ... Q14: ='Set a analizar'!Q320 -> 0 | S14: d | T14: =T11-T13/100 -> 0.45 | U14: m | Y14: 12 | Z14: =PI()*(Y14/2)^2 -> 113.09734 | AB14: =AA14*Z14 -> 0 | AD14: 12 | AE14: =PI()*(AD14/2)^2 -> 113.09734 | AG14: =AF14*AE14 -> 0
B15: ='Set a analizar'!B321 -> -1 | C15: ='Set a analizar'!C321 -> B8 | D15: ='Set a analizar'!D321 -> 8 | E15: ='Set a analizar'!E321 -> PP | F15: ='Set a analizar'!F321 -> LinStatic | G15: ='Set a analizar'!G321 -> 0 | H15: ='Set a analizar'!H321 -> 3.9541 | I15: ='Set a analizar'!I321 -> 0 | ... Q15: ='Set a analizar'!Q321 -> 0 | Y15: 16 | Z15: =PI()*(Y15/2)^2 -> 201.06193 | AB15: =AA15*Z15 -> 0 | AD15: 16 | AE15: =PI()*(AD15/2)^2 -> 201.06193 | AG15: =AF15*AE15 -> 0
B16: ='Set a analizar'!B322 -> -1 | C16: ='Set a analizar'!C322 -> B8 | D16: ='Set a analizar'!D322 -> 8 | E16: ='Set a analizar'!E322 -> PP | F16: ='Set a analizar'!F322 -> LinStatic | G16: ='Set a analizar'!G322 -> 0 | H16: ='Set a analizar'!H322 -> 3.9541 | I16: ='Set a analizar'!I322 -> 0 | ... Q16: ='Set a analizar'!Q322 -> 0 | S16: Características | Y16: 18 | Z16: =PI()*(Y16/2)^2 -> 254.469 | AA16: 3 | AB16: =AA16*Z16 -> 763.40701 | AD16: 18 | AE16: =PI()*(AD16/2)^2 -> 254.469 | AF16: 0 | AG16: =AF16*AE16 -> 0
B17: ='Set a analizar'!B323 -> -1 | C17: ='Set a analizar'!C323 -> B8 | D17: ='Set a analizar'!D323 -> 8 | E17: ='Set a analizar'!E323 -> PP | F17: ='Set a analizar'!F323 -> LinStatic | G17: ='Set a analizar'!G323 -> 0 | H17: ='Set a analizar'!H323 -> 4.4531 | I17: ='Set a analizar'!I323 -> 0 | ... Q17: ='Set a analizar'!Q323 -> 0 | Y17: 22 | Z17: =PI()*(Y17/2)^2 -> 380.13271 | AA17: 0 | AB17: =AA17*Z17 -> 0 | AD17: 22 | AE17: =PI()*(AD17/2)^2 -> 380.13271 | AF17: 0 | AG17: =AF17*AE17 -> 0
B18: ='Set a analizar'!B324 -> -1 | C18: ='Set a analizar'!C324 -> B8 | D18: ='Set a analizar'!D324 -> 8 | E18: ='Set a analizar'!E324 -> PP | F18: ='Set a analizar'!F324 -> LinStatic | G18: ='Set a analizar'!G324 -> 0 | H18: ='Set a analizar'!H324 -> 4.9521 | I18: ='Set a analizar'!I324 -> 0 | ... Q18: ='Set a analizar'!Q324 -> 0 | S18: f'c | T18: 35 | U18: Mpa | Y18: 25 | Z18: =PI()*(Y18/2)^2 -> 490.87385 | AB18: =AA18*Z18 -> 0 | AD18: 25 | AE18: =PI()*(AD18/2)^2 -> 490.87385 | AG18: =AF18*AE18 -> 0
B19: ='Set a analizar'!B325 -> -1 | C19: ='Set a analizar'!C325 -> B8 | D19: ='Set a analizar'!D325 -> 8 | E19: ='Set a analizar'!E325 -> PP | F19: ='Set a analizar'!F325 -> LinStatic | G19: ='Set a analizar'!G325 -> 0 | H19: ='Set a analizar'!H325 -> 4.9521 | I19: ='Set a analizar'!I325 -> 0 | ... Q19: ='Set a analizar'!Q325 -> 0 | S19: E | T19: =4700*(SQRT(T18))/1000 -> 27.805575 | U19: Gpa | Y19: 28 | Z19: =PI()*(Y19/2)^2 -> 615.75216 | AB19: =AA19*Z19 -> 0 | AD19: 28 | AE19: =PI()*(AD19/2)^2 -> 615.75216 | AG19: =AF19*AE19 -> 0
B20: ='Set a analizar'!B326 -> -1 | C20: ='Set a analizar'!C326 -> B8 | D20: ='Set a analizar'!D326 -> 8 | E20: ='Set a analizar'!E326 -> PP | F20: ='Set a analizar'!F326 -> LinStatic | G20: ='Set a analizar'!G326 -> 0 | H20: ='Set a analizar'!H326 -> 5.3761 | I20: ='Set a analizar'!I326 -> 0 | ... Q20: ='Set a analizar'!Q326 -> 0 | S20: f'c | T20: =T18*9.81*10 -> 3433.5 | U20: tonf/m^2 | Y20: 32 | Z20: =PI()*(Y20/2)^2 -> 804.24772 | AB20: =AA20*Z20 -> 0 | AD20: 32 | AE20: =PI()*(AD20/2)^2 -> 804.24772 | AG20: =AF20*AE20 -> 0
B21: ='Set a analizar'!B327 -> -1 | C21: ='Set a analizar'!C327 -> B8 | D21: ='Set a analizar'!D327 -> 8 | E21: ='Set a analizar'!E327 -> PP | F21: ='Set a analizar'!F327 -> LinStatic | G21: ='Set a analizar'!G327 -> 0 | H21: ='Set a analizar'!H327 -> 5.8001 | I21: ='Set a analizar'!I327 -> 0 | ... Q21: ='Set a analizar'!Q327 -> 0 | S21: E | T21: =151*((T20/10)^0.5)/1000*(1000*1000) -> 2797985.6 | U21: tonf/m^2 | Y21: 36 | Z21: =PI()*(Y21/2)^2 -> 1017.876 | AB21: =AA21*Z21 -> 0 | AD21: 36 | AE21: =PI()*(AD21/2)^2 -> 1017.876 | AG21: =AF21*AE21 -> 0
B22: ='Set a analizar'!B328 -> -1 | C22: ='Set a analizar'!C328 -> B8 | D22: ='Set a analizar'!D328 -> 8 | E22: ='Set a analizar'!E328 -> SC | F22: ='Set a analizar'!F328 -> LinStatic | G22: ='Set a analizar'!G328 -> 0 | H22: ='Set a analizar'!H328 -> 0.15 | I22: ='Set a analizar'!I328 -> 0 | ... Q22: ='Set a analizar'!Q328 -> 0 | S22: I | T22: =((T11^3)*(T12))/12 -> 0.0026041667 | U22: m^4 | Y22: 40 | Z22: =PI()*(Y22/2)^2 -> 1256.6371 | AB22: =AA22*Z22 -> 0 | AD22: 40 | AE22: =PI()*(AD22/2)^2 -> 1256.6371 | AG22: =AF22*AE22 -> 0
B23: ='Set a analizar'!B329 -> -1 | C23: ='Set a analizar'!C329 -> B8 | D23: ='Set a analizar'!D329 -> 8 | E23: ='Set a analizar'!E329 -> SC | F23: ='Set a analizar'!F329 -> LinStatic | G23: ='Set a analizar'!G329 -> 0 | H23: ='Set a analizar'!H329 -> 0.555 | I23: ='Set a analizar'!I329 -> 0 | ... Q23: ='Set a analizar'!Q329 -> 0 | S23: fy | T23: 420 | U23: MPa
B24: ='Set a analizar'!B330 -> -1 | C24: ='Set a analizar'!C330 -> B8 | D24: ='Set a analizar'!D330 -> 8 | E24: ='Set a analizar'!E330 -> SC | F24: ='Set a analizar'!F330 -> LinStatic | G24: ='Set a analizar'!G330 -> 0 | H24: ='Set a analizar'!H330 -> 0.96 | I24: ='Set a analizar'!I330 -> 0 | ... Q24: ='Set a analizar'!Q330 -> 0 | S24: fy | T24: =T23*98.1 -> 41202 | U24: tonf/m^2 | Y24: Área máxima | AB24: =T46*1000*1000 -> 2390.625 | AC24: mm^2
B25: ='Set a analizar'!B331 -> -1 | C25: ='Set a analizar'!C331 -> B8 | D25: ='Set a analizar'!D331 -> 8 | E25: ='Set a analizar'!E331 -> SC | F25: ='Set a analizar'!F331 -> LinStatic | G25: ='Set a analizar'!G331 -> 0 | H25: ='Set a analizar'!H331 -> 0.96 | I25: ='Set a analizar'!I331 -> 0 | ... Q25: ='Set a analizar'!Q331 -> 0 | S25: e_c | T25: 0.003 | Y25: Área mínima | AB25: =T39*10*10 -> 375 | AC25: mm^2
B26: ='Set a analizar'!B332 -> -1 | C26: ='Set a analizar'!C332 -> B8 | D26: ='Set a analizar'!D332 -> 8 | E26: ='Set a analizar'!E332 -> SC | F26: ='Set a analizar'!F332 -> LinStatic | G26: ='Set a analizar'!G332 -> 0 | H26: ='Set a analizar'!H332 -> 1.459 | I26: ='Set a analizar'!I332 -> 0 | ... Q26: ='Set a analizar'!Q332 -> 0 | S26: e_y | T26: 0.002 | Y26: Área | AB26: =SUM(AB12:AB22) -> 763.40701 | AD26: Área | AG26: =SUM(AG12:AG22) -> 50.265482
B27: ='Set a analizar'!B333 -> -1 | C27: ='Set a analizar'!C333 -> B8 | D27: ='Set a analizar'!D333 -> 8 | E27: ='Set a analizar'!E333 -> SC | F27: ='Set a analizar'!F333 -> LinStatic | G27: ='Set a analizar'!G333 -> 0 | H27: ='Set a analizar'!H333 -> 1.958 | I27: ='Set a analizar'!I333 -> 0 | ... Q27: ='Set a analizar'!Q333 -> 0 | S27: A_g | T27: =T11*T12 -> 0.125 | U27: m^2 | Y27: check | AB27: =IF(AND(AB25<AB26,AB26<AB24),"Estas bien","tay fuera") -> Estas bien
B28: ='Set a analizar'!B334 -> -1 | C28: ='Set a analizar'!C334 -> B8 | D28: ='Set a analizar'!D334 -> 8 | E28: ='Set a analizar'!E334 -> SC | F28: ='Set a analizar'!F334 -> LinStatic | G28: ='Set a analizar'!G334 -> 0 | H28: ='Set a analizar'!H334 -> 1.958 | I28: ='Set a analizar'!I334 -> 0 | ... Q28: ='Set a analizar'!Q334 -> 0
B29: ='Set a analizar'!B335 -> -1 | C29: ='Set a analizar'!C335 -> B8 | D29: ='Set a analizar'!D335 -> 8 | E29: ='Set a analizar'!E335 -> SC | F29: ='Set a analizar'!F335 -> LinStatic | G29: ='Set a analizar'!G335 -> 0 | H29: ='Set a analizar'!H335 -> 2.457 | I29: ='Set a analizar'!I335 -> 0 | ... Q29: ='Set a analizar'!Q335 -> 0
B30: ='Set a analizar'!B336 -> -1 | C30: ='Set a analizar'!C336 -> B8 | D30: ='Set a analizar'!D336 -> 8 | E30: ='Set a analizar'!E336 -> SC | F30: ='Set a analizar'!F336 -> LinStatic | G30: ='Set a analizar'!G336 -> 0 | H30: ='Set a analizar'!H336 -> 2.956 | I30: ='Set a analizar'!I336 -> 0 | ... Q30: ='Set a analizar'!Q336 -> 0 | S30: Cálculo de flexión | W30: Cálculo de corte
B31: ='Set a analizar'!B337 -> -1 | C31: ='Set a analizar'!C337 -> B8 | D31: ='Set a analizar'!D337 -> 8 | E31: ='Set a analizar'!E337 -> SC | F31: ='Set a analizar'!F337 -> LinStatic | G31: ='Set a analizar'!G337 -> 0 | H31: ='Set a analizar'!H337 -> 2.956 | I31: ='Set a analizar'!I337 -> 0 | ... Q31: ='Set a analizar'!Q337 -> 0
B32: ='Set a analizar'!B338 -> -1 | C32: ='Set a analizar'!C338 -> B8 | D32: ='Set a analizar'!D338 -> 8 | E32: ='Set a analizar'!E338 -> SC | F32: ='Set a analizar'!F338 -> LinStatic | G32: ='Set a analizar'!G338 -> 0 | H32: ='Set a analizar'!H338 -> 3.455 | I32: ='Set a analizar'!I338 -> 0 | ... Q32: ='Set a analizar'!Q338 -> 0
B33: ='Set a analizar'!B339 -> -1 | C33: ='Set a analizar'!C339 -> B8 | D33: ='Set a analizar'!D339 -> 8 | E33: ='Set a analizar'!E339 -> SC | F33: ='Set a analizar'!F339 -> LinStatic | G33: ='Set a analizar'!G339 -> 0 | H33: ='Set a analizar'!H339 -> 3.9541 | I33: ='Set a analizar'!I339 -> 0 | ... Q33: ='Set a analizar'!Q339 -> 0
B34: ='Set a analizar'!B340 -> -1 | C34: ='Set a analizar'!C340 -> B8 | D34: ='Set a analizar'!D340 -> 8 | E34: ='Set a analizar'!E340 -> SC | F34: ='Set a analizar'!F340 -> LinStatic | G34: ='Set a analizar'!G340 -> 0 | H34: ='Set a analizar'!H340 -> 3.9541 | I34: ='Set a analizar'!I340 -> 0 | ... Q34: ='Set a analizar'!Q340 -> 0
B35: ='Set a analizar'!B341 -> -1 | C35: ='Set a analizar'!C341 -> B8 | D35: ='Set a analizar'!D341 -> 8 | E35: ='Set a analizar'!E341 -> SC | F35: ='Set a analizar'!F341 -> LinStatic | G35: ='Set a analizar'!G341 -> 0 | H35: ='Set a analizar'!H341 -> 4.4531 | I35: ='Set a analizar'!I341 -> 0 | ... Q35: ='Set a analizar'!Q341 -> 0 | S35: Parámetros importantes | W35: Resistencia del hormigón al corte
B36: ='Set a analizar'!B342 -> -1 | C36: ='Set a analizar'!C342 -> B8 | D36: ='Set a analizar'!D342 -> 8 | E36: ='Set a analizar'!E342 -> SC | F36: ='Set a analizar'!F342 -> LinStatic | G36: ='Set a analizar'!G342 -> 0 | H36: ='Set a analizar'!H342 -> 4.9521 | I36: ='Set a analizar'!I342 -> 0 | ... Q36: ='Set a analizar'!Q342 -> 0 | S36: Enfierradura mínima | W36: V_u | X36: =T7*9.81 -> 100.60547 | Y36: kN
B37: ='Set a analizar'!B343 -> -1 | C37: ='Set a analizar'!C343 -> B8 | D37: ='Set a analizar'!D343 -> 8 | E37: ='Set a analizar'!E343 -> SC | F37: ='Set a analizar'!F343 -> LinStatic | G37: ='Set a analizar'!G343 -> 0 | H37: ='Set a analizar'!H343 -> 4.9521 | I37: ='Set a analizar'!I343 -> 0 | ... Q37: ='Set a analizar'!Q343 -> 0 | S37: As_min1 | T37: =(0.25*SQRT(T18))/T23*T11*T12*100*100 -> 4.4018451 | U37: cm^2 | W37: V_c | X37: =0.17*1*SQRT(T18)*T12*T14*1000*1000/1000 -> 113.14503 | Y37: kN
B38: ='Set a analizar'!B344 -> -1 | C38: ='Set a analizar'!C344 -> B8 | D38: ='Set a analizar'!D344 -> 8 | E38: ='Set a analizar'!E344 -> SC | F38: ='Set a analizar'!F344 -> LinStatic | G38: ='Set a analizar'!G344 -> 0 | H38: ='Set a analizar'!H344 -> 5.3761 | I38: ='Set a analizar'!I344 -> 0 | ... Q38: ='Set a analizar'!Q344 -> 0 | S38: As_min2 | T38: =1.4*T14*T12/T23*100*100 -> 3.75 | U38: cm^2 | W38: Factor | X38: =0.75*(X37+0.66*SQRT(T18)*T12*T14*1000) -> 414.31046 | Y38: kN
B39: ='Set a analizar'!B345 -> -1 | C39: ='Set a analizar'!C345 -> B8 | D39: ='Set a analizar'!D345 -> 8 | E39: ='Set a analizar'!E345 -> SC | F39: ='Set a analizar'!F345 -> LinStatic | G39: ='Set a analizar'!G345 -> 0 | H39: ='Set a analizar'!H345 -> 5.8001 | I39: ='Set a analizar'!I345 -> 0 | ... Q39: ='Set a analizar'!Q345 -> 0 | S39: As_min | T39: =MIN(T37:T38) -> 3.75 | U39: cm^2
B40: ='Set a analizar'!B346 -> -1 | C40: ='Set a analizar'!C346 -> B8 | D40: ='Set a analizar'!D346 -> 8 | E40: ='Set a analizar'!E346 -> SX | F40: ='Set a analizar'!F346 -> LinRespSpec | G40: ='Set a analizar'!G346 -> Max | H40: ='Set a analizar'!H346 -> 0.15 | I40: ='Set a analizar'!I346 -> 0 | ... Q40: ='Set a analizar'!Q346 -> 0 | S40: rho_min | T40: =T39/(T12*100*T14*100) -> 0.0033333333 | W40: Se requiere armadura?
B41: ='Set a analizar'!B347 -> -1 | C41: ='Set a analizar'!C347 -> B8 | D41: ='Set a analizar'!D347 -> 8 | E41: ='Set a analizar'!E347 -> SX | F41: ='Set a analizar'!F347 -> LinRespSpec | G41: ='Set a analizar'!G347 -> Max | H41: ='Set a analizar'!H347 -> 0.555 | I41: ='Set a analizar'!I347 -> 0 | ... Q41: ='Set a analizar'!Q347 -> 0 | W41: 0.9*V_c/2 | X41: =0.75*X37/2 -> 42.429385
...

Sheet B15
B2: Story | C2: Beam | D2: Unique Name | E2: Output Case | F2: Case Type | G2: Step Type | H2: Station | I2: P | J2: V2 | K2: V3 | L2: T | M2: M2 | N2: M3 | O2: Element | P2: Elem Station | Q2: Location
H3: m | I3: tonf | J3: tonf | K3: tonf | L3: tonf-m | M3: tonf-m | N3: tonf-m | P3: m
B4: ='Set a analizar'!B616 -> -1 | C4: ='Set a analizar'!C616 -> B15 | D4: ='Set a analizar'!D616 -> 15 | E4: ='Set a analizar'!E616 -> PP | F4: ='Set a analizar'!F616 -> LinStatic | G4: ='Set a analizar'!G616 -> 0 | H4: ='Set a analizar'!H616 -> 0.15 | I4: ='Set a analizar'!I616 -> 0 | ... Q4: ='Set a analizar'!Q616 -> 0 | S4: Mmax | T4: =MAX(N4:N309) -> 6.3142 | U4: tonfm
B5: ='Set a analizar'!B617 -> -1 | C5: ='Set a analizar'!C617 -> B15 | D5: ='Set a analizar'!D617 -> 15 | E5: ='Set a analizar'!E617 -> PP | F5: ='Set a analizar'!F617 -> LinStatic | G5: ='Set a analizar'!G617 -> 0 | H5: ='Set a analizar'!H617 -> 0.49 | I5: ='Set a analizar'!I617 -> 0 | ... Q5: ='Set a analizar'!Q617 -> 0 | S5: Mmin | T5: =MIN(N4:N309) -> -19.4211 | U5: tonfm | AA5: fc | AB5: =T18 -> 35 | AC5: 0.85
B6: ='Set a analizar'!B618 -> -1 | C6: ='Set a analizar'!C618 -> B15 | D6: ='Set a analizar'!D618 -> 15 | E6: ='Set a analizar'!E618 -> PP | F6: ='Set a analizar'!F618 -> LinStatic | G6: ='Set a analizar'!G618 -> 0 | H6: ='Set a analizar'!H618 -> 0.83 | I6: ='Set a analizar'!I618 -> 0 | ... Q6: ='Set a analizar'!Q618 -> 0 | AC6: 0.65
B7: ='Set a analizar'!B619 -> -1 | C7: ='Set a analizar'!C619 -> B15 | D7: ='Set a analizar'!D619 -> 15 | E7: ='Set a analizar'!E619 -> PP | F7: ='Set a analizar'!F619 -> LinStatic | G7: ='Set a analizar'!G619 -> 0 | H7: ='Set a analizar'!H619 -> 0.83 | I7: ='Set a analizar'!I619 -> 0 | ... Q7: ='Set a analizar'!Q619 -> 0 | S7: Vmax | T7: =MAX(J4:J309) -> 12.7914 | U7: tonf | AC7: =0.85-(0.05*(AB5-28)/7) -> 0.8
B8: ='Set a analizar'!B620 -> -1 | C8: ='Set a analizar'!C620 -> B15 | D8: ='Set a analizar'!D620 -> 15 | E8: ='Set a analizar'!E620 -> PP | F8: ='Set a analizar'!F620 -> LinStatic | G8: ='Set a analizar'!G620 -> 0 | H8: ='Set a analizar'!H620 -> 1.2449 | I8: ='Set a analizar'!I620 -> 0 | ... Q8: ='Set a analizar'!Q620 -> 0 | S8: Vmin | T8: =MIN(J4:J309) -> -9.9924 | U8: tonf
B9: ='Set a analizar'!B621 -> -1 | C9: ='Set a analizar'!C621 -> B15 | D9: ='Set a analizar'!D621 -> 15 | E9: ='Set a analizar'!E621 -> PP | F9: ='Set a analizar'!F621 -> LinStatic | G9: ='Set a analizar'!G621 -> 0 | H9: ='Set a analizar'!H621 -> 1.6599 | I9: ='Set a analizar'!I621 -> 0 | ... Q9: ='Set a analizar'!Q621 -> 0 | Y9: Flexión | AD9: Corte
B10: ='Set a analizar'!B622 -> -1 | C10: ='Set a analizar'!C622 -> B15 | D10: ='Set a analizar'!D622 -> 15 | E10: ='Set a analizar'!E622 -> PP | F10: ='Set a analizar'!F622 -> LinStatic | G10: ='Set a analizar'!G622 -> 0 | H10: ='Set a analizar'!H622 -> 1.6599 | I10: ='Set a analizar'!I622 -> 0 | ... Q10: ='Set a analizar'!Q622 -> 0 | S10: Geometría del perfil | Y10: Diámetro | Z10: Área | AA10: Unidades | AB10: Área total | AD10: Diámetro | AE10: Área | AF10: Unidades | AG10: Área total
B11: ='Set a analizar'!B623 -> -1 | C11: ='Set a analizar'!C623 -> B15 | D11: ='Set a analizar'!D623 -> 15 | E11: ='Set a analizar'!E623 -> PP | F11: ='Set a analizar'!F623 -> LinStatic | G11: ='Set a analizar'!G623 -> 0 | H11: ='Set a analizar'!H623 -> 2.1347 | I11: ='Set a analizar'!I623 -> 0 | ... Q11: ='Set a analizar'!Q623 -> 0 | S11: h | T11: 0.5 | U11: m | Y11: mm | Z11: mm^2 | AB11: mm^2 | AD11: mm | AE11: mm^2 | AG11: mm^2
B12: ='Set a analizar'!B624 -> -1 | C12: ='Set a analizar'!C624 -> B15 | D12: ='Set a analizar'!D624 -> 15 | E12: ='Set a analizar'!E624 -> PP | F12: ='Set a analizar'!F624 -> LinStatic | G12: ='Set a analizar'!G624 -> 0 | H12: ='Set a analizar'!H624 -> 2.6095 | I12: ='Set a analizar'!I624 -> 0 | ... Q12: ='Set a analizar'!Q624 -> 0 | S12: b | T12: 0.25 | U12: m | Y12: 8 | Z12: =PI()*(Y12/2)^2 -> 50.265482 | AB12: =AA12*Z12 -> 0 | AD12: 8 | AE12: =PI()*(AD12/2)^2 -> 50.265482 | AF12: 1 | AG12: =AF12*AE12 -> 50.265482
B13: ='Set a analizar'!B625 -> -1 | C13: ='Set a analizar'!C625 -> B15 | D13: ='Set a analizar'!D625 -> 15 | E13: ='Set a analizar'!E625 -> PP | F13: ='Set a analizar'!F625 -> LinStatic | G13: ='Set a analizar'!G625 -> 0 | H13: ='Set a analizar'!H625 -> 2.6095 | I13: ='Set a analizar'!I625 -> 0 | ... Q13: ='Set a analizar'!Q625 -> 0 | S13: rec | T13: 5 | U13: cm | Y13: 10 | Z13: =PI()*(Y13/2)^2 -> 78.539816 | AB13: =AA13*Z13 -> 0 | AD13: 10 | AE13: =PI()*(AD13/2)^2 -> 78.539816 | AG13: =AF13*AE13 -> 0
B14: ='Set a analizar'!B626 -> -1 | C14: ='Set a analizar'!C626 -> B15 | D14: ='Set a analizar'!D626 -> 15 | E14: ='Set a analizar'!E626 -> PP | F14: ='Set a analizar'!F626 -> LinStatic | G14: ='Set a analizar'!G626 -> 0 | H14: ='Set a analizar'!H626 -> 3.0844 | I14: ='Set a analizar'!I626 -> 0 | ... Q14: ='Set a analizar'!Q626 -> 0 | S14: d | T14: =T11-T13/100 -> 0.45 | U14: m | Y14: 12 | Z14: =PI()*(Y14/2)^2 -> 113.09734 | AB14: =AA14*Z14 -> 0 | AD14: 12 | AE14: =PI()*(AD14/2)^2 -> 113.09734 | AG14: =AF14*AE14 -> 0
B15: ='Set a analizar'!B627 -> -1 | C15: ='Set a analizar'!C627 -> B15 | D15: ='Set a analizar'!D627 -> 15 | E15: ='Set a analizar'!E627 -> PP | F15: ='Set a analizar'!F627 -> LinStatic | G15: ='Set a analizar'!G627 -> 0 | H15: ='Set a analizar'!H627 -> 3.5592 | I15: ='Set a analizar'!I627 -> 0 | ... Q15: ='Set a analizar'!Q627 -> 0 | Y15: 16 | Z15: =PI()*(Y15/2)^2 -> 201.06193 | AB15: =AA15*Z15 -> 0 | AD15: 16 | AE15: =PI()*(AD15/2)^2 -> 201.06193 | AG15: =AF15*AE15 -> 0
B16: ='Set a analizar'!B628 -> -1 | C16: ='Set a analizar'!C628 -> B15 | D16: ='Set a analizar'!D628 -> 15 | E16: ='Set a analizar'!E628 -> PP | F16: ='Set a analizar'!F628 -> LinStatic | G16: ='Set a analizar'!G628 -> 0 | H16: ='Set a analizar'!H628 -> 3.5592 | I16: ='Set a analizar'!I628 -> 0 | ... Q16: ='Set a analizar'!Q628 -> 0 | S16: Características | Y16: 18 | Z16: =PI()*(Y16/2)^2 -> 254.469 | AA16: 0 | AB16: =AA16*Z16 -> 0 | AD16: 18 | AE16: =PI()*(AD16/2)^2 -> 254.469 | AF16: 0 | AG16: =AF16*AE16 -> 0
B17: ='Set a analizar'!B629 -> -1 | C17: ='Set a analizar'!C629 -> B15 | D17: ='Set a analizar'!D629 -> 15 | E17: ='Set a analizar'!E629 -> PP | F17: ='Set a analizar'!F629 -> LinStatic | G17: ='Set a analizar'!G629 -> 0 | H17: ='Set a analizar'!H629 -> 4.034 | I17: ='Set a analizar'!I629 -> 0 | ... Q17: ='Set a analizar'!Q629 -> 0 | Y17: 22 | Z17: =PI()*(Y17/2)^2 -> 380.13271 | AA17: 4 | AB17: =AA17*Z17 -> 1520.5308 | AD17: 22 | AE17: =PI()*(AD17/2)^2 -> 380.13271 | AF17: 0 | AG17: =AF17*AE17 -> 0
B18: ='Set a analizar'!B630 -> -1 | C18: ='Set a analizar'!C630 -> B15 | D18: ='Set a analizar'!D630 -> 15 | E18: ='Set a analizar'!E630 -> PP | F18: ='Set a analizar'!F630 -> LinStatic | G18: ='Set a analizar'!G630 -> 0 | H18: ='Set a analizar'!H630 -> 4.5088 | I18: ='Set a analizar'!I630 -> 0 | ... Q18: ='Set a analizar'!Q630 -> 0 | S18: f'c | T18: 35 | U18: Mpa | Y18: 25 | Z18: =PI()*(Y18/2)^2 -> 490.87385 | AB18: =AA18*Z18 -> 0 | AD18: 25 | AE18: =PI()*(AD18/2)^2 -> 490.87385 | AG18: =AF18*AE18 -> 0
B19: ='Set a analizar'!B631 -> -1 | C19: ='Set a analizar'!C631 -> B15 | D19: ='Set a analizar'!D631 -> 15 | E19: ='Set a analizar'!E631 -> PP | F19: ='Set a analizar'!F631 -> LinStatic | G19: ='Set a analizar'!G631 -> 0 | H19: ='Set a analizar'!H631 -> 4.5088 | I19: ='Set a analizar'!I631 -> 0 | ... Q19: ='Set a analizar'!Q631 -> 0 | S19: E | T19: =4700*(SQRT(T18))/1000 -> 27.805575 | U19: Gpa | Y19: 28 | Z19: =PI()*(Y19/2)^2 -> 615.75216 | AB19: =AA19*Z19 -> 0 | AD19: 28 | AE19: =PI()*(AD19/2)^2 -> 615.75216 | AG19: =AF19*AE19 -> 0
B20: ='Set a analizar'!B632 -> -1 | C20: ='Set a analizar'!C632 -> B15 | D20: ='Set a analizar'!D632 -> 15 | E20: ='Set a analizar'!E632 -> PP | F20: ='Set a analizar'!F632 -> LinStatic | G20: ='Set a analizar'!G632 -> 0 | H20: ='Set a analizar'!H632 -> 4.9836 | I20: ='Set a analizar'!I632 -> 0 | ... Q20: ='Set a analizar'!Q632 -> 0 | S20: f'c | T20: =T18*9.81*10 -> 3433.5 | U20: tonf/m^2 | Y20: 32 | Z20: =PI()*(Y20/2)^2 -> 804.24772 | AB20: =AA20*Z20 -> 0 | AD20: 32 | AE20: =PI()*(AD20/2)^2 -> 804.24772 | AG20: =AF20*AE20 -> 0
B21: ='Set a analizar'!B633 -> -1 | C21: ='Set a analizar'!C633 -> B15 | D21: ='Set a analizar'!D633 -> 15 | E21: ='Set a analizar'!E633 -> PP | F21: ='Set a analizar'!F633 -> LinStatic | G21: ='Set a analizar'!G633 -> 0 | H21: ='Set a analizar'!H633 -> 5.4584 | I21: ='Set a analizar'!I633 -> 0 | ... Q21: ='Set a analizar'!Q633 -> 0 | S21: E | T21: =151*((T20/10)^0.5)/1000*(1000*1000) -> 2797985.6 | U21: tonf/m^2 | Y21: 36 | Z21: =PI()*(Y21/2)^2 -> 1017.876 | AB21: =AA21*Z21 -> 0 | AD21: 36 | AE21: =PI()*(AD21/2)^2 -> 1017.876 | AG21: =AF21*AE21 -> 0
B22: ='Set a analizar'!B634 -> -1 | C22: ='Set a analizar'!C634 -> B15 | D22: ='Set a analizar'!D634 -> 15 | E22: ='Set a analizar'!E634 -> PP | F22: ='Set a analizar'!F634 -> LinStatic | G22: ='Set a analizar'!G634 -> 0 | H22: ='Set a analizar'!H634 -> 5.4584 | I22: ='Set a analizar'!I634 -> 0 | ... Q22: ='Set a analizar'!Q634 -> 0 | S22: I | T22: =((T11^3)*(T12))/12 -> 0.0026041667 | U22: m^4 | Y22: 40 | Z22: =PI()*(Y22/2)^2 -> 1256.6371 | AB22: =AA22*Z22 -> 0 | AD22: 40 | AE22: =PI()*(AD22/2)^2 -> 1256.6371 | AG22: =AF22*AE22 -> 0
B23: ='Set a analizar'!B635 -> -1 | C23: ='Set a analizar'!C635 -> B15 | D23: ='Set a analizar'!D635 -> 15 | E23: ='Set a analizar'!E635 -> PP | F23: ='Set a analizar'!F635 -> LinStatic | G23: ='Set a analizar'!G635 -> 0 | H23: ='Set a analizar'!H635 -> 5.8582 | I23: ='Set a analizar'!I635 -> 0 | ... Q23: ='Set a analizar'!Q635 -> 0 | S23: fy | T23: 420 | U23: MPa
B24: ='Set a analizar'!B636 -> -1 | C24: ='Set a analizar'!C636 -> B15 | D24: ='Set a analizar'!D636 -> 15 | E24: ='Set a analizar'!E636 -> PP | F24: ='Set a analizar'!F636 -> LinStatic | G24: ='Set a analizar'!G636 -> 0 | H24: ='Set a analizar'!H636 -> 6.2581 | I24: ='Set a analizar'!I636 -> 0 | ... Q24: ='Set a analizar'!Q636 -> 0 | S24: fy | T24: =T23*98.1 -> 41202 | U24: tonf/m^2 | Y24: Área máxima | AB24: =T46*1000*1000 -> 2390.625 | AC24: mm^2
B25: ='Set a analizar'!B637 -> -1 | C25: ='Set a analizar'!C637 -> B15 | D25: ='Set a analizar'!D637 -> 15 | E25: ='Set a analizar'!E637 -> SC | F25: ='Set a analizar'!F637 -> LinStatic | G25: ='Set a analizar'!G637 -> 0 | H25: ='Set a analizar'!H637 -> 0.15 | I25: ='Set a analizar'!I637 -> 0 | ... Q25: ='Set a analizar'!Q637 -> 0 | S25: e_c | T25: 0.003 | Y25: Área mínima | AB25: =T39*10*10 -> 375 | AC25: mm^2
B26: ='Set a analizar'!B638 -> -1 | C26: ='Set a analizar'!C638 -> B15 | D26: ='Set a analizar'!D638 -> 15 | E26: ='Set a analizar'!E638 -> SC | F26: ='Set a analizar'!F638 -> LinStatic | G26: ='Set a analizar'!G638 -> 0 | H26: ='Set a analizar'!H638 -> 0.49 | I26: ='Set a analizar'!I638 -> 0 | ... Q26: ='Set a analizar'!Q638 -> 0 | S26: e_y | T26: 0.002 | Y26: Área | AB26: =SUM(AB12:AB22) -> 1520.5308 | AD26: Área | AG26: =SUM(AG12:AG22) -> 50.265482
B27: ='Set a analizar'!B639 -> -1 | C27: ='Set a analizar'!C639 -> B15 | D27: ='Set a analizar'!D639 -> 15 | E27: ='Set a analizar'!E639 -> SC | F27: ='Set a analizar'!F639 -> LinStatic | G27: ='Set a analizar'!G639 -> 0 | H27: ='Set a analizar'!H639 -> 0.83 | I27: ='Set a analizar'!I639 -> 0 | ... Q27: ='Set a analizar'!Q639 -> 0 | S27: A_g | T27: =T11*T12 -> 0.125 | U27: m^2 | Y27: check | AB27: =IF(AND(AB25<AB26,AB26<AB24),"Estas bien","tay fuera") -> Estas bien
B28: ='Set a analizar'!B640 -> -1 | C28: ='Set a analizar'!C640 -> B15 | D28: ='Set a analizar'!D640 -> 15 | E28: ='Set a analizar'!E640 -> SC | F28: ='Set a analizar'!F640 -> LinStatic | G28: ='Set a analizar'!G640 -> 0 | H28: ='Set a analizar'!H640 -> 0.83 | I28: ='Set a analizar'!I640 -> 0 | ... Q28: ='Set a analizar'!Q640 -> 0
B29: ='Set a analizar'!B641 -> -1 | C29: ='Set a analizar'!C641 -> B15 | D29: ='Set a analizar'!D641 -> 15 | E29: ='Set a analizar'!E641 -> SC | F29: ='Set a analizar'!F641 -> LinStatic | G29: ='Set a analizar'!G641 -> 0 | H29: ='Set a analizar'!H641 -> 1.2449 | I29: ='Set a analizar'!I641 -> 0 | ... Q29: ='Set a analizar'!Q641 -> 0
B30: ='Set a analizar'!B642 -> -1 | C30: ='Set a analizar'!C642 -> B15 | D30: ='Set a analizar'!D642 -> 15 | E30: ='Set a analizar'!E642 -> SC | F30: ='Set a analizar'!F642 -> LinStatic | G30: ='Set a analizar'!G642 -> 0 | H30: ='Set a analizar'!H642 -> 1.6599 | I30: ='Set a analizar'!I642 -> 0 | ... Q30: ='Set a analizar'!Q642 -> 0 | S30: Cálculo de flexión | W30: Cálculo de corte
B31: ='Set a analizar'!B643 -> -1 | C31: ='Set a analizar'!C643 -> B15 | D31: ='Set a analizar'!D643 -> 15 | E31: ='Set a analizar'!E643 -> SC | F31: ='Set a analizar'!F643 -> LinStatic | G31: ='Set a analizar'!G643 -> 0 | H31: ='Set a analizar'!H643 -> 1.6599 | I31: ='Set a analizar'!I643 -> 0 | ... Q31: ='Set a analizar'!Q643 -> 0
B32: ='Set a analizar'!B644 -> -1 | C32: ='Set a analizar'!C644 -> B15 | D32: ='Set a analizar'!D644 -> 15 | E32: ='Set a analizar'!E644 -> SC | F32: ='Set a analizar'!F644 -> LinStatic | G32: ='Set a analizar'!G644 -> 0 | H32: ='Set a analizar'!H644 -> 2.1347 | I32: ='Set a analizar'!I644 -> 0 | ... Q32: ='Set a analizar'!Q644 -> 0
B33: ='Set a analizar'!B645 -> -1 | C33: ='Set a analizar'!C645 -> B15 | D33: ='Set a analizar'!D645 -> 15 | E33: ='Set a analizar'!E645 -> SC | F33: ='Set a analizar'!F645 -> LinStatic | G33: ='Set a analizar'!G645 -> 0 | H33: ='Set a analizar'!H645 -> 2.6095 | I33: ='Set a analizar'!I645 -> 0 | ... Q33: ='Set a analizar'!Q645 -> 0
B34: ='Set a analizar'!B646 -> -1 | C34: ='Set a analizar'!C646 -> B15 | D34: ='Set a analizar'!D646 -> 15 | E34: ='Set a analizar'!E646 -> SC | F34: ='Set a analizar'!F646 -> LinStatic | G34: ='Set a analizar'!G646 -> 0 | H34: ='Set a analizar'!H646 -> 2.6095 | I34: ='Set a analizar'!I646 -> 0 | ... Q34: ='Set a analizar'!Q646 -> 0
B35: ='Set a analizar'!B647 -> -1 | C35: ='Set a analizar'!C647 -> B15 | D35: ='Set a analizar'!D647 -> 15 | E35: ='Set a analizar'!E647 -> SC | F35: ='Set a analizar'!F647 -> LinStatic | G35: ='Set a analizar'!G647 -> 0 | H35: ='Set a analizar'!H647 -> 3.0844 | I35: ='Set a analizar'!I647 -> 0 | ... Q35: ='Set a analizar'!Q647 -> 0 | S35: Parámetros importantes | W35: Resistencia del hormigón al corte
B36: ='Set a analizar'!B648 -> -1 | C36: ='Set a analizar'!C648 -> B15 | D36: ='Set a analizar'!D648 -> 15 | E36: ='Set a analizar'!E648 -> SC | F36: ='Set a analizar'!F648 -> LinStatic | G36: ='Set a analizar'!G648 -> 0 | H36: ='Set a analizar'!H648 -> 3.5592 | I36: ='Set a analizar'!I648 -> 0 | ... Q36: ='Set a analizar'!Q648 -> 0 | S36: Enfierradura mínima | W36: V_u | X36: =T7*9.81 -> 125.48363 | Y36: kN
B37: ='Set a analizar'!B649 -> -1 | C37: ='Set a analizar'!C649 -> B15 | D37: ='Set a analizar'!D649 -> 15 | E37: ='Set a analizar'!E649 -> SC | F37: ='Set a analizar'!F649 -> LinStatic | G37: ='Set a analizar'!G649 -> 0 | H37: ='Set a analizar'!H649 -> 3.5592 | I37: ='Set a analizar'!I649 -> 0 | ... Q37: ='Set a analizar'!Q649 -> 0 | S37: As_min1 | T37: =(0.25*SQRT(T18))/T23*T11*T12*100*100 -> 4.4018451 | U37: cm^2 | W37: V_c | X37: =0.17*1*SQRT(T18)*T12*T14*1000*1000/1000 -> 113.14503 | Y37: kN
B38: ='Set a analizar'!B650 -> -1 | C38: ='Set a analizar'!C650 -> B15 | D38: ='Set a analizar'!D650 -> 15 | E38: ='Set a analizar'!E650 -> SC | F38: ='Set a analizar'!F650 -> LinStatic | G38: ='Set a analizar'!G650 -> 0 | H38: ='Set a analizar'!H650 -> 4.034 | I38: ='Set a analizar'!I650 -> 0 | ... Q38: ='Set a analizar'!Q650 -> 0 | S38: As_min2 | T38: =1.4*T14*T12/T23*100*100 -> 3.75 | U38: cm^2 | W38: Factor | X38: =0.75*(X37+0.66*SQRT(T18)*T12*T14*1000) -> 414.31046 | Y38: kN
B39: ='Set a analizar'!B651 -> -1 | C39: ='Set a analizar'!C651 -> B15 | D39: ='Set a analizar'!D651 -> 15 | E39: ='Set a analizar'!E651 -> SC | F39: ='Set a analizar'!F651 -> LinStatic | G39: ='Set a analizar'!G651 -> 0 | H39: ='Set a analizar'!H651 -> 4.5088 | I39: ='Set a analizar'!I651 -> 0 | ... Q39: ='Set a analizar'!Q651 -> 0 | S39: As_min | T39: =MIN(T37:T38) -> 3.75 | U39: cm^2
B40: ='Set a analizar'!B652 -> -1 | C40: ='Set a analizar'!C652 -> B15 | D40: ='Set a analizar'!D652 -> 15 | E40: ='Set a analizar'!E652 -> SC | F40: ='Set a analizar'!F652 -> LinStatic | G40: ='Set a analizar'!G652 -> 0 | H40: ='Set a analizar'!H652 -> 4.5088 | I40: ='Set a analizar'!I652 -> 0 | ... Q40: ='Set a analizar'!Q652 -> 0 | S40: rho_min | T40: =T39/(T12*100*T14*100) -> 0.0033333333 | W40: Se requiere armadura?
B41: ='Set a analizar'!B653 -> -1 | C41: ='Set a analizar'!C653 -> B15 | D41: ='Set a analizar'!D653 -> 15 | E41: ='Set a analizar'!E653 -> SC | F41: ='Set a analizar'!F653 -> LinStatic | G41: ='Set a analizar'!G653 -> 0 | H41: ='Set a analizar'!H653 -> 4.9836 | I41: ='Set a analizar'!I653 -> 0 | ... Q41: ='Set a analizar'!Q653 -> 0 | W41: 0.9*V_c/2 | X41: =0.75*X37/2 -> 42.429385
...

Sheet B16
B2: Story | C2: Beam | D2: Unique Name | E2: Output Case | F2: Case Type | G2: Step Type | H2: Station | I2: P | J2: V2 | K2: V3 | L2: T | M2: M2 | N2: M3 | O2: Element | P2: Elem Station | Q2: Location
H3: m | I3: tonf | J3: tonf | K3: tonf | L3: tonf-m | M3: tonf-m | N3: tonf-m | P3: m
B4: ='Set a analizar'!B973 -> -1 | C4: ='Set a analizar'!C973 -> B16 | D4: ='Set a analizar'!D973 -> 16 | E4: ='Set a analizar'!E973 -> PP | F4: ='Set a analizar'!F973 -> LinStatic | G4: ='Set a analizar'!G973 -> 0 | H4: ='Set a analizar'!H973 -> 0.15 | I4: ='Set a analizar'!I973 -> 0 | ... Q4: ='Set a analizar'!Q973 -> 0 | S4: Mmax | T4: =MAX(N4:N309) -> 18.1265 | U4: tonfm
B5: ='Set a analizar'!B974 -> -1 | C5: ='Set a analizar'!C974 -> B16 | D5: ='Set a analizar'!D974 -> 16 | E5: ='Set a analizar'!E974 -> PP | F5: ='Set a analizar'!F974 -> LinStatic | G5: ='Set a analizar'!G974 -> 0 | H5: ='Set a analizar'!H974 -> 0.5255 | I5: ='Set a analizar'!I974 -> 0 | ... Q5: ='Set a analizar'!Q974 -> 0 | S5: Mmin | T5: =MIN(N4:N309) -> -24.2641 | U5: tonfm | AA5: fc | AB5: =T18 -> 35 | AC5: 0.85
B6: ='Set a analizar'!B975 -> -1 | C6: ='Set a analizar'!C975 -> B16 | D6: ='Set a analizar'!D975 -> 16 | E6: ='Set a analizar'!E975 -> PP | F6: ='Set a analizar'!F975 -> LinStatic | G6: ='Set a analizar'!G975 -> 0 | H6: ='Set a analizar'!H975 -> 0.9009 | I6: ='Set a analizar'!I975 -> 0 | ... Q6: ='Set a analizar'!Q975 -> 0 | AC6: 0.65
B7: ='Set a analizar'!B976 -> -1 | C7: ='Set a analizar'!C976 -> B16 | D7: ='Set a analizar'!D976 -> 16 | E7: ='Set a analizar'!E976 -> PP | F7: ='Set a analizar'!F976 -> LinStatic | G7: ='Set a analizar'!G976 -> 0 | H7: ='Set a analizar'!H976 -> 0.9009 | I7: ='Set a analizar'!I976 -> 0 | ... Q7: ='Set a analizar'!Q976 -> 0 | S7: Vmax | T7: =MAX(J4:J309) -> 9.5796 | U7: tonf | AC7: =0.85-(0.05*(AB5-28)/7) -> 0.8
B8: ='Set a analizar'!B977 -> -1 | C8: ='Set a analizar'!C977 -> B16 | D8: ='Set a analizar'!D977 -> 16 | E8: ='Set a analizar'!E977 -> PP | F8: ='Set a analizar'!F977 -> LinStatic | G8: ='Set a analizar'!G977 -> 0 | H8: ='Set a analizar'!H977 -> 1.3514 | I8: ='Set a analizar'!I977 -> 0 | ... Q8: ='Set a analizar'!Q977 -> 0 | S8: Vmin | T8: =MIN(J4:J309) -> -17.6096 | U8: tonf
B9: ='Set a analizar'!B978 -> -1 | C9: ='Set a analizar'!C978 -> B16 | D9: ='Set a analizar'!D978 -> 16 | E9: ='Set a analizar'!E978 -> PP | F9: ='Set a analizar'!F978 -> LinStatic | G9: ='Set a analizar'!G978 -> 0 | H9: ='Set a analizar'!H978 -> 1.8019 | I9: ='Set a analizar'!I978 -> 0 | ... Q9: ='Set a analizar'!Q978 -> 0 | Y9: Flexión | AD9: Corte
B10: ='Set a analizar'!B979 -> -1 | C10: ='Set a analizar'!C979 -> B16 | D10: ='Set a analizar'!D979 -> 16 | E10: ='Set a analizar'!E979 -> PP | F10: ='Set a analizar'!F979 -> LinStatic | G10: ='Set a analizar'!G979 -> 0 | H10: ='Set a analizar'!H979 -> 1.8019 | I10: ='Set a analizar'!I979 -> 0 | ... Q10: ='Set a analizar'!Q979 -> 0 | S10: Geometría del perfil | Y10: Diámetro | Z10: Área | AA10: Unidades | AB10: Área total | AD10: Diámetro | AE10: Área | AF10: Unidades | AG10: Área total
B11: ='Set a analizar'!B980 -> -1 | C11: ='Set a analizar'!C980 -> B16 | D11: ='Set a analizar'!D980 -> 16 | E11: ='Set a analizar'!E980 -> PP | F11: ='Set a analizar'!F980 -> LinStatic | G11: ='Set a analizar'!G980 -> 0 | H11: ='Set a analizar'!H980 -> 2.2697 | I11: ='Set a analizar'!I980 -> 0 | ... Q11: ='Set a analizar'!Q980 -> 0 | S11: h | T11: 0.5 | U11: m | Y11: mm | Z11: mm^2 | AB11: mm^2 | AD11: mm | AE11: mm^2 | AG11: mm^2
