Workbook

Sheet Resultados
A1: Resumen consolidado V2 / M3 / P por Muro, Pier y Caso
A2: Sección | B2: Pier | C2: Output Case | D2: V2 max | E2: V2 min | F2: M3 max | G2: M3 min | H2: P max | I2: P min
D3: tonf | E3: tonf | F3: tonf-m | G3: tonf-m | H3: tonf | I3: tonf
A4: MURO PERIMETRAL | B4: P1 | C4: PP | D4: =_xlfn.MAXIFS('MURO PERIMETRAL'!$I$4:$I$173,'MURO PERIMETRAL'!$C$4:$C$173,$B4,'MURO PERIMETRAL'!$D$4:$D$173,$C4) -> 90.758 | E4: =_xlfn.MINIFS('MURO PERIMETRAL'!$I$4:$I$173,'MURO PERIMETRAL'!$C$4:$C$173,$B4,'MURO PERIMETRAL'!$D$4:$D$173,$C4) -> 90.758 | F4: =_xlfn.MAXIFS('MURO PERIMETRAL'!$M$4:$M$173,'MURO PERIMETRAL'!$C$4:$C$173,$B4,'MURO PERIMETRAL'!$D$4:$D$173,$C4) -> 310.252 | G4: =_xlfn.MINIFS('MURO PERIMETRAL'!$M$4:$M$173,'MURO PERIMETRAL'!$C$4:$C$173,$B4,'MURO PERIMETRAL'!$D$4:$D$173,$C4) -> 74.2811 | H4: =_xlfn.MAXIFS('MURO PERIMETRAL'!$H$4:$H$173,'MURO PERIMETRAL'!$C$4:$C$173,$B4,'MURO PERIMETRAL'!$D$4:$D$173,$C4) -> -41.5256 | I4: =_xlfn.MINIFS('MURO PERIMETRAL'!$H$4:$H$173,'MURO PERIMETRAL'!$C$4:$C$173,$B4,'MURO PERIMETRAL'!$D$4:$D$173,$C4) -> -103.2006
A5: MURO PERIMETRAL | B5: P1 | C5: SC | D5: =_xlfn.MAXIFS('MURO PERIMETRAL'!$I$4:$I$173,'MURO PERIMETRAL'!$C$4:$C$173,$B5,'MURO PERIMETRAL'!$D$4:$D$173,$C5) -> 80.9317 | E5: =_xlfn.MINIFS('MURO PERIMETRAL'!$I$4:$I$173,'MURO PERIMETRAL'!$C$4:$C$173,$B5,'MURO PERIMETRAL'!$D$4:$D$173,$C5) -> 80.9317 | F5: =_xlfn.MAXIFS('MURO PERIMETRAL'!$M$4:$M$173,'MURO PERIMETRAL'!$C$4:$C$173,$B5,'MURO PERIMETRAL'!$D$4:$D$173,$C5) -> 294.5399 | G5: =_xlfn.MINIFS('MURO PERIMETRAL'!$M$4:$M$173,'MURO PERIMETRAL'!$C$4:$C$173,$B5,'MURO PERIMETRAL'!$D$4:$D$173,$C5) -> 84.1175 | H5: =_xlfn.MAXIFS('MURO PERIMETRAL'!$H$4:$H$173,'MURO PERIMETRAL'!$C$4:$C$173,$B5,'MURO PERIMETRAL'!$D$4:$D$173,$C5) -> -39.1494 | I5: =_xlfn.MINIFS('MURO PERIMETRAL'!$H$4:$H$173,'MURO PERIMETRAL'!$C$4:$C$173,$B5,'MURO PERIMETRAL'!$D$4:$D$173,$C5) -> -39.1494
A6: MURO PERIMETRAL | B6: P1 | C6: SX | D6: =_xlfn.MAXIFS('MURO PERIMETRAL'!$I$4:$I$173,'MURO PERIMETRAL'!$C$4:$C$173,$B6,'MURO PERIMETRAL'!$D$4:$D$173,$C6) -> 105.4009 | E6: =_xlfn.MINIFS('MURO PERIMETRAL'!$I$4:$I$173,'MURO PERIMETRAL'!$C$4:$C$173,$B6,'MURO PERIMETRAL'!$D$4:$D$173,$C6) -> 105.4009 | F6: =_xlfn.MAXIFS('MURO PERIMETRAL'!$M$4:$M$173,'MURO PERIMETRAL'!$C$4:$C$173,$B6,'MURO PERIMETRAL'!$D$4:$D$173,$C6) -> 294.3905 | G6: =_xlfn.MINIFS('MURO PERIMETRAL'!$M$4:$M$173,'MURO PERIMETRAL'!$C$4:$C$173,$B6,'MURO PERIMETRAL'!$D$4:$D$173,$C6) -> 87.9462 | H6: =_xlfn.MAXIFS('MURO PERIMETRAL'!$H$4:$H$173,'MURO PERIMETRAL'!$C$4:$C$173,$B6,'MURO PERIMETRAL'!$D$4:$D$173,$C6) -> 5.0862 | I6: =_xlfn.MINIFS('MURO PERIMETRAL'!$H$4:$H$173,'MURO PERIMETRAL'!$C$4:$C$173,$B6,'MURO PERIMETRAL'!$D$4:$D$173,$C6) -> 5.0862
A7: MURO PERIMETRAL | B7: P1 | C7: SY | D7: =_xlfn.MAXIFS('MURO PERIMETRAL'!$I$4:$I$173,'MURO PERIMETRAL'!$C$4:$C$173,$B7,'MURO PERIMETRAL'!$D$4:$D$173,$C7) -> 210.3668 | E7: =_xlfn.MINIFS('MURO PERIMETRAL'!$I$4:$I$173,'MURO PERIMETRAL'!$C$4:$C$173,$B7,'MURO PERIMETRAL'!$D$4:$D$173,$C7) -> 210.3668 | F7: =_xlfn.MAXIFS('MURO PERIMETRAL'!$M$4:$M$173,'MURO PERIMETRAL'!$C$4:$C$173,$B7,'MURO PERIMETRAL'!$D$4:$D$173,$C7) -> 403.9666 | G7: =_xlfn.MINIFS('MURO PERIMETRAL'!$M$4:$M$173,'MURO PERIMETRAL'!$C$4:$C$173,$B7,'MURO PERIMETRAL'!$D$4:$D$173,$C7) -> 143.8221 | H7: =_xlfn.MAXIFS('MURO PERIMETRAL'!$H$4:$H$173,'MURO PERIMETRAL'!$C$4:$C$173,$B7,'MURO PERIMETRAL'!$D$4:$D$173,$C7) -> 5.5207 | I7: =_xlfn.MINIFS('MURO PERIMETRAL'!$H$4:$H$173,'MURO PERIMETRAL'!$C$4:$C$173,$B7,'MURO PERIMETRAL'!$D$4:$D$173,$C7) -> 5.5207
A8: MURO PERIMETRAL | B8: PN | C8: PP | D8: =_xlfn.MAXIFS('MURO PERIMETRAL'!$I$4:$I$173,'MURO PERIMETRAL'!$C$4:$C$173,$B8,'MURO PERIMETRAL'!$D$4:$D$173,$C8) -> -21.5459 | E8: =_xlfn.MINIFS('MURO PERIMETRAL'!$I$4:$I$173,'MURO PERIMETRAL'!$C$4:$C$173,$B8,'MURO PERIMETRAL'!$D$4:$D$173,$C8) -> -21.5459 | F8: =_xlfn.MAXIFS('MURO PERIMETRAL'!$M$4:$M$173,'MURO PERIMETRAL'!$C$4:$C$173,$B8,'MURO PERIMETRAL'!$D$4:$D$173,$C8) -> 27.3762 | G8: =_xlfn.MINIFS('MURO PERIMETRAL'!$M$4:$M$173,'MURO PERIMETRAL'!$C$4:$C$173,$B8,'MURO PERIMETRAL'!$D$4:$D$173,$C8) -> -28.6432 | H8: =_xlfn.MAXIFS('MURO PERIMETRAL'!$H$4:$H$173,'MURO PERIMETRAL'!$C$4:$C$173,$B8,'MURO PERIMETRAL'!$D$4:$D$173,$C8) -> -36.7532 | I8: =_xlfn.MINIFS('MURO PERIMETRAL'!$H$4:$H$173,'MURO PERIMETRAL'!$C$4:$C$173,$B8,'MURO PERIMETRAL'!$D$4:$D$173,$C8) -> -70.8132
A9: MURO PERIMETRAL | B9: PN | C9: SC | D9: =_xlfn.MAXIFS('MURO PERIMETRAL'!$I$4:$I$173,'MURO PERIMETRAL'!$C$4:$C$173,$B9,'MURO PERIMETRAL'!$D$4:$D$173,$C9) -> -23.4705 | E9: =_xlfn.MINIFS('MURO PERIMETRAL'!$I$4:$I$173,'MURO PERIMETRAL'!$C$4:$C$173,$B9,'MURO PERIMETRAL'!$D$4:$D$173,$C9) -> -23.4705 | F9: =_xlfn.MAXIFS('MURO PERIMETRAL'!$M$4:$M$173,'MURO PERIMETRAL'!$C$4:$C$173,$B9,'MURO PERIMETRAL'!$D$4:$D$173,$C9) -> 28.6637 | G9: =_xlfn.MINIFS('MURO PERIMETRAL'!$M$4:$M$173,'MURO PERIMETRAL'!$C$4:$C$173,$B9,'MURO PERIMETRAL'!$D$4:$D$173,$C9) -> -32.3595 | H9: =_xlfn.MAXIFS('MURO PERIMETRAL'!$H$4:$H$173,'MURO PERIMETRAL'!$C$4:$C$173,$B9,'MURO PERIMETRAL'!$D$4:$D$173,$C9) -> -35.1075 | I9: =_xlfn.MINIFS('MURO PERIMETRAL'!$H$4:$H$173,'MURO PERIMETRAL'!$C$4:$C$173,$B9,'MURO PERIMETRAL'!$D$4:$D$173,$C9) -> -35.1075
A10: MURO PERIMETRAL | B10: PN | C10: SX | D10: =_xlfn.MAXIFS('MURO PERIMETRAL'!$I$4:$I$173,'MURO PERIMETRAL'!$C$4:$C$173,$B10,'MURO PERIMETRAL'!$D$4:$D$173,$C10) -> 156.9326 | E10: =_xlfn.MINIFS('MURO PERIMETRAL'!$I$4:$I$173,'MURO PERIMETRAL'!$C$4:$C$173,$B10,'MURO PERIMETRAL'!$D$4:$D$173,$C10) -> 156.9326 | F10: =_xlfn.MAXIFS('MURO PERIMETRAL'!$M$4:$M$173,'MURO PERIMETRAL'!$C$4:$C$173,$B10,'MURO PERIMETRAL'!$D$4:$D$173,$C10) -> 273.4855 | G10: =_xlfn.MINIFS('MURO PERIMETRAL'!$M$4:$M$173,'MURO PERIMETRAL'!$C$4:$C$173,$B10,'MURO PERIMETRAL'!$D$4:$D$173,$C10) -> 134.7712 | H10: =_xlfn.MAXIFS('MURO PERIMETRAL'!$H$4:$H$173,'MURO PERIMETRAL'!$C$4:$C$173,$B10,'MURO PERIMETRAL'!$D$4:$D$173,$C10) -> 3.1064 | I10: =_xlfn.MINIFS('MURO PERIMETRAL'!$H$4:$H$173,'MURO PERIMETRAL'!$C$4:$C$173,$B10,'MURO PERIMETRAL'!$D$4:$D$173,$C10) -> 3.1064
A11: MURO PERIMETRAL | B11: PN | C11: SY | D11: =_xlfn.MAXIFS('MURO PERIMETRAL'!$I$4:$I$173,'MURO PERIMETRAL'!$C$4:$C$173,$B11,'MURO PERIMETRAL'!$D$4:$D$173,$C11) -> 34.6338 | E11: =_xlfn.MINIFS('MURO PERIMETRAL'!$I$4:$I$173,'MURO PERIMETRAL'!$C$4:$C$173,$B11,'MURO PERIMETRAL'!$D$4:$D$173,$C11) -> 34.6338 | F11: =_xlfn.MAXIFS('MURO PERIMETRAL'!$M$4:$M$173,'MURO PERIMETRAL'!$C$4:$C$173,$B11,'MURO PERIMETRAL'!$D$4:$D$173,$C11) -> 68.2735 | G11: =_xlfn.MINIFS('MURO PERIMETRAL'!$M$4:$M$173,'MURO PERIMETRAL'!$C$4:$C$173,$B11,'MURO PERIMETRAL'!$D$4:$D$173,$C11) -> 34.489 | H11: =_xlfn.MAXIFS('MURO PERIMETRAL'!$H$4:$H$173,'MURO PERIMETRAL'!$C$4:$C$173,$B11,'MURO PERIMETRAL'!$D$4:$D$173,$C11) -> 12.2056 | I11: =_xlfn.MINIFS('MURO PERIMETRAL'!$H$4:$H$173,'MURO PERIMETRAL'!$C$4:$C$173,$B11,'MURO PERIMETRAL'!$D$4:$D$173,$C11) -> 12.2056
A12: MURO PERIMETRAL | B12: P13 | C12: PP | D12: =_xlfn.MAXIFS('MURO PERIMETRAL'!$I$4:$I$173,'MURO PERIMETRAL'!$C$4:$C$173,$B12,'MURO PERIMETRAL'!$D$4:$D$173,$C12) -> -19.9414 | E12: =_xlfn.MINIFS('MURO PERIMETRAL'!$I$4:$I$173,'MURO PERIMETRAL'!$C$4:$C$173,$B12,'MURO PERIMETRAL'!$D$4:$D$173,$C12) -> -19.9414 | F12: =_xlfn.MAXIFS('MURO PERIMETRAL'!$M$4:$M$173,'MURO PERIMETRAL'!$C$4:$C$173,$B12,'MURO PERIMETRAL'!$D$4:$D$173,$C12) -> 52.6255 | G12: =_xlfn.MINIFS('MURO PERIMETRAL'!$M$4:$M$173,'MURO PERIMETRAL'!$C$4:$C$173,$B12,'MURO PERIMETRAL'!$D$4:$D$173,$C12) -> 0.7779 | H12: =_xlfn.MAXIFS('MURO PERIMETRAL'!$H$4:$H$173,'MURO PERIMETRAL'!$C$4:$C$173,$B12,'MURO PERIMETRAL'!$D$4:$D$173,$C12) -> -39.3749 | I12: =_xlfn.MINIFS('MURO PERIMETRAL'!$H$4:$H$173,'MURO PERIMETRAL'!$C$4:$C$173,$B12,'MURO PERIMETRAL'!$D$4:$D$173,$C12) -> -78.6609
A13: MURO PERIMETRAL | B13: P13 | C13: SC | D13: =_xlfn.MAXIFS('MURO PERIMETRAL'!$I$4:$I$173,'MURO PERIMETRAL'!$C$4:$C$173,$B13,'MURO PERIMETRAL'!$D$4:$D$173,$C13) -> -11.4693 | E13: =_xlfn.MINIFS('MURO PERIMETRAL'!$I$4:$I$173,'MURO PERIMETRAL'!$C$4:$C$173,$B13,'MURO PERIMETRAL'!$D$4:$D$173,$C13) -> -11.4693 | F13: =_xlfn.MAXIFS('MURO PERIMETRAL'!$M$4:$M$173,'MURO PERIMETRAL'!$C$4:$C$173,$B13,'MURO PERIMETRAL'!$D$4:$D$173,$C13) -> 36.2713 | G13: =_xlfn.MINIFS('MURO PERIMETRAL'!$M$4:$M$173,'MURO PERIMETRAL'!$C$4:$C$173,$B13,'MURO PERIMETRAL'!$D$4:$D$173,$C13) -> 6.4511 | H13: =_xlfn.MAXIFS('MURO PERIMETRAL'!$H$4:$H$173,'MURO PERIMETRAL'!$C$4:$C$173,$B13,'MURO PERIMETRAL'!$D$4:$D$173,$C13) -> -38.2734 | I13: =_xlfn.MINIFS('MURO PERIMETRAL'!$H$4:$H$173,'MURO PERIMETRAL'!$C$4:$C$173,$B13,'MURO PERIMETRAL'!$D$4:$D$173,$C13) -> -38.2734
A14: MURO PERIMETRAL | B14: P13 | C14: SX | D14: =_xlfn.MAXIFS('MURO PERIMETRAL'!$I$4:$I$173,'MURO PERIMETRAL'!$C$4:$C$173,$B14,'MURO PERIMETRAL'!$D$4:$D$173,$C14) -> 77.8666 | E14: =_xlfn.MINIFS('MURO PERIMETRAL'!$I$4:$I$173,'MURO PERIMETRAL'!$C$4:$C$173,$B14,'MURO PERIMETRAL'!$D$4:$D$173,$C14) -> 77.8666 | F14: =_xlfn.MAXIFS('MURO PERIMETRAL'!$M$4:$M$173,'MURO PERIMETRAL'!$C$4:$C$173,$B14,'MURO PERIMETRAL'!$D$4:$D$173,$C14) -> 147.5598 | G14: =_xlfn.MINIFS('MURO PERIMETRAL'!$M$4:$M$173,'MURO PERIMETRAL'!$C$4:$C$173,$B14,'MURO PERIMETRAL'!$D$4:$D$173,$C14) -> 57.8965 | H14: =_xlfn.MAXIFS('MURO PERIMETRAL'!$H$4:$H$173,'MURO PERIMETRAL'!$C$4:$C$173,$B14,'MURO PERIMETRAL'!$D$4:$D$173,$C14) -> 21.565 | I14: =_xlfn.MINIFS('MURO PERIMETRAL'!$H$4:$H$173,'MURO PERIMETRAL'!$C$4:$C$173,$B14,'MURO PERIMETRAL'!$D$4:$D$173,$C14) -> 21.565
A15: MURO PERIMETRAL | B15: P13 | C15: SY | D15: =_xlfn.MAXIFS('MURO PERIMETRAL'!$I$4:$I$173,'MURO PERIMETRAL'!$C$4:$C$173,$B15,'MURO PERIMETRAL'!$D$4:$D$173,$C15) -> 190.2291 | E15: =_xlfn.MINIFS('MURO PERIMETRAL'!$I$4:$I$173,'MURO PERIMETRAL'!$C$4:$C$173,$B15,'MURO PERIMETRAL'!$D$4:$D$173,$C15) -> 190.2291 | F15: =_xlfn.MAXIFS('MURO PERIMETRAL'!$M$4:$M$173,'MURO PERIMETRAL'!$C$4:$C$173,$B15,'MURO PERIMETRAL'!$D$4:$D$173,$C15) -> 401.1794 | G15: =_xlfn.MINIFS('MURO PERIMETRAL'!$M$4:$M$173,'MURO PERIMETRAL'!$C$4:$C$173,$B15,'MURO PERIMETRAL'!$D$4:$D$173,$C15) -> 93.4796 | H15: =_xlfn.MAXIFS('MURO PERIMETRAL'!$H$4:$H$173,'MURO PERIMETRAL'!$C$4:$C$173,$B15,'MURO PERIMETRAL'!$D$4:$D$173,$C15) -> 7.682 | I15: =_xlfn.MINIFS('MURO PERIMETRAL'!$H$4:$H$173,'MURO PERIMETRAL'!$C$4:$C$173,$B15,'MURO PERIMETRAL'!$D$4:$D$173,$C15) -> 7.682
... A23: MURO PERIMETRAL | B23: P12 | C23: SY | D23: =_xlfn.MAXIFS('MURO PERIMETRAL'!$I$4:$I$173,'MURO PERIMETRAL'!$C$4:$C$173,$B23,'MURO PERIMETRAL'!$D$4:$D$173,$C23) -> 58.8195 | E23: =_xlfn.MINIFS('MURO PERIMETRAL'!$I$4:$I$173,'MURO PERIMETRAL'!$C$4:$C$173,$B23,'MURO PERIMETRAL'!$D$4:$D$173,$C23) -> 58.8195 | F23: =_xlfn.MAXIFS('MURO PERIMETRAL'!$M$4:$M$173,'MURO PERIMETRAL'!$C$4:$C$173,$B23,'MURO PERIMETRAL'!$D$4:$D$173,$C23) -> 125.3613 | G23: =_xlfn.MINIFS('MURO PERIMETRAL'!$M$4:$M$173,'MURO PERIMETRAL'!$C$4:$C$173,$B23,'MURO PERIMETRAL'!$D$4:$D$173,$C23) -> 33.6955 | H23: =_xlfn.MAXIFS('MURO PERIMETRAL'!$H$4:$H$173,'MURO PERIMETRAL'!$C$4:$C$173,$B23,'MURO PERIMETRAL'!$D$4:$D$173,$C23) -> 2.8078 | I23: =_xlfn.MINIFS('MURO PERIMETRAL'!$H$4:$H$173,'MURO PERIMETRAL'!$C$4:$C$173,$B23,'MURO PERIMETRAL'!$D$4:$D$173,$C23) -> 2.8078
A24: 2 | B24: P3-L-J | C24: PP | D24: =_xlfn.MAXIFS('2'!$I$4:$I$70,'2'!$C$4:$C$70,$B24,'2'!$D$4:$D$70,$C24) -> -3.3482 | E24: =_xlfn.MINIFS('2'!$I$4:$I$70,'2'!$C$4:$C$70,$B24,'2'!$D$4:$D$70,$C24) -> -3.3482 | F24: =_xlfn.MAXIFS('2'!$M$4:$M$70,'2'!$C$4:$C$70,$B24,'2'!$D$4:$D$70,$C24) -> -1.3797 | G24: =_xlfn.MINIFS('2'!$M$4:$M$70,'2'!$C$4:$C$70,$B24,'2'!$D$4:$D$70,$C24) -> -10.0851 | H24: =_xlfn.MAXIFS('2'!$H$4:$H$70,'2'!$C$4:$C$70,$B24,'2'!$D$4:$D$70,$C24) -> -312.6755 | I24: =_xlfn.MINIFS('2'!$H$4:$H$70,'2'!$C$4:$C$70,$B24,'2'!$D$4:$D$70,$C24) -> -318.8505
A25: 2 | B25: P3-L-J | C25: SC | D25: =_xlfn.MAXIFS('2'!$I$4:$I$70,'2'!$C$4:$C$70,$B25,'2'!$D$4:$D$70,$C25) -> -5.8105 | E25: =_xlfn.MINIFS('2'!$I$4:$I$70,'2'!$C$4:$C$70,$B25,'2'!$D$4:$D$70,$C25) -> -5.8105 | F25: =_xlfn.MAXIFS('2'!$M$4:$M$70,'2'!$C$4:$C$70,$B25,'2'!$D$4:$D$70,$C25) -> 7.1279 | G25: =_xlfn.MINIFS('2'!$M$4:$M$70,'2'!$C$4:$C$70,$B25,'2'!$D$4:$D$70,$C25) -> -7.9795 | H25: =_xlfn.MAXIFS('2'!$H$4:$H$70,'2'!$C$4:$C$70,$B25,'2'!$D$4:$D$70,$C25) -> -77.0185 | I25: =_xlfn.MINIFS('2'!$H$4:$H$70,'2'!$C$4:$C$70,$B25,'2'!$D$4:$D$70,$C25) -> -77.0185
A26: 2 | B26: P3-L-J | C26: SX | D26: =_xlfn.MAXIFS('2'!$I$4:$I$70,'2'!$C$4:$C$70,$B26,'2'!$D$4:$D$70,$C26) -> 19.2948 | E26: =_xlfn.MINIFS('2'!$I$4:$I$70,'2'!$C$4:$C$70,$B26,'2'!$D$4:$D$70,$C26) -> 19.2948 | F26: =_xlfn.MAXIFS('2'!$M$4:$M$70,'2'!$C$4:$C$70,$B26,'2'!$D$4:$D$70,$C26) -> 72.2021 | G26: =_xlfn.MINIFS('2'!$M$4:$M$70,'2'!$C$4:$C$70,$B26,'2'!$D$4:$D$70,$C26) -> 32.249 | H26: =_xlfn.MAXIFS('2'!$H$4:$H$70,'2'!$C$4:$C$70,$B26,'2'!$D$4:$D$70,$C26) -> 181.0766 | I26: =_xlfn.MINIFS('2'!$H$4:$H$70,'2'!$C$4:$C$70,$B26,'2'!$D$4:$D$70,$C26) -> 181.0766
A27: 2 | B27: P3-L-J | C27: SY | D27: =_xlfn.MAXIFS('2'!$I$4:$I$70,'2'!$C$4:$C$70,$B27,'2'!$D$4:$D$70,$C27) -> 10.468 | E27: =_xlfn.MINIFS('2'!$I$4:$I$70,'2'!$C$4:$C$70,$B27,'2'!$D$4:$D$70,$C27) -> 10.468 | F27: =_xlfn.MAXIFS('2'!$M$4:$M$70,'2'!$C$4:$C$70,$B27,'2'!$D$4:$D$70,$C27) -> 97.0486 | G27: =_xlfn.MINIFS('2'!$M$4:$M$70,'2'!$C$4:$C$70,$B27,'2'!$D$4:$D$70,$C27) -> 79.7643 | H27: =_xlfn.MAXIFS('2'!$H$4:$H$70,'2'!$C$4:$C$70,$B27,'2'!$D$4:$D$70,$C27) -> 156.9889 | I27: =_xlfn.MINIFS('2'!$H$4:$H$70,'2'!$C$4:$C$70,$B27,'2'!$D$4:$D$70,$C27) -> 156.9889
A28: 2 | B28: P3-L | C28: PP | D28: =_xlfn.MAXIFS('2'!$I$4:$I$70,'2'!$C$4:$C$70,$B28,'2'!$D$4:$D$70,$C28) -> 0.6774 | E28: =_xlfn.MINIFS('2'!$I$4:$I$70,'2'!$C$4:$C$70,$B28,'2'!$D$4:$D$70,$C28) -> 0.6774 | F28: =_xlfn.MAXIFS('2'!$M$4:$M$70,'2'!$C$4:$C$70,$B28,'2'!$D$4:$D$70,$C28) -> 0.4567 | G28: =_xlfn.MINIFS('2'!$M$4:$M$70,'2'!$C$4:$C$70,$B28,'2'!$D$4:$D$70,$C28) -> -1.3045 | H28: =_xlfn.MAXIFS('2'!$H$4:$H$70,'2'!$C$4:$C$70,$B28,'2'!$D$4:$D$70,$C28) -> -100.2474 | I28: =_xlfn.MINIFS('2'!$H$4:$H$70,'2'!$C$4:$C$70,$B28,'2'!$D$4:$D$70,$C28) -> -102.3315
A29: 2 | B29: P3-L | C29: SC | D29: =_xlfn.MAXIFS('2'!$I$4:$I$70,'2'!$C$4:$C$70,$B29,'2'!$D$4:$D$70,$C29) -> 1.0106 | E29: =_xlfn.MINIFS('2'!$I$4:$I$70,'2'!$C$4:$C$70,$B29,'2'!$D$4:$D$70,$C29) -> 1.0106 | F29: =_xlfn.MAXIFS('2'!$M$4:$M$70,'2'!$C$4:$C$70,$B29,'2'!$D$4:$D$70,$C29) -> 0.9079 | G29: =_xlfn.MINIFS('2'!$M$4:$M$70,'2'!$C$4:$C$70,$B29,'2'!$D$4:$D$70,$C29) -> -1.7198 | H29: =_xlfn.MAXIFS('2'!$H$4:$H$70,'2'!$C$4:$C$70,$B29,'2'!$D$4:$D$70,$C29) -> -23.7904 | I29: =_xlfn.MINIFS('2'!$H$4:$H$70,'2'!$C$4:$C$70,$B29,'2'!$D$4:$D$70,$C29) -> -23.7904
A30: 2 | B30: P3-L | C30: SX | D30: =_xlfn.MAXIFS('2'!$I$4:$I$70,'2'!$C$4:$C$70,$B30,'2'!$D$4:$D$70,$C30) -> 9.656 | E30: =_xlfn.MINIFS('2'!$I$4:$I$70,'2'!$C$4:$C$70,$B30,'2'!$D$4:$D$70,$C30) -> 9.656 | F30: =_xlfn.MAXIFS('2'!$M$4:$M$70,'2'!$C$4:$C$70,$B30,'2'!$D$4:$D$70,$C30) -> 16.5241 | G30: =_xlfn.MINIFS('2'!$M$4:$M$70,'2'!$C$4:$C$70,$B30,'2'!$D$4:$D$70,$C30) -> 10.5132 | H30: =_xlfn.MAXIFS('2'!$H$4:$H$70,'2'!$C$4:$C$70,$B30,'2'!$D$4:$D$70,$C30) -> 75.8029 | I30: =_xlfn.MINIFS('2'!$H$4:$H$70,'2'!$C$4:$C$70,$B30,'2'!$D$4:$D$70,$C30) -> 75.8029
A31: 2 | B31: P3-L | C31: SY | D31: =_xlfn.MAXIFS('2'!$I$4:$I$70,'2'!$C$4:$C$70,$B31,'2'!$D$4:$D$70,$C31) -> 5.4243 | E31: =_xlfn.MINIFS('2'!$I$4:$I$70,'2'!$C$4:$C$70,$B31,'2'!$D$4:$D$70,$C31) -> 5.4243 | F31: =_xlfn.MAXIFS('2'!$M$4:$M$70,'2'!$C$4:$C$70,$B31,'2'!$D$4:$D$70,$C31) -> 8.6388 | G31: =_xlfn.MINIFS('2'!$M$4:$M$70,'2'!$C$4:$C$70,$B31,'2'!$D$4:$D$70,$C31) -> 5.4658 | H31: =_xlfn.MAXIFS('2'!$H$4:$H$70,'2'!$C$4:$C$70,$B31,'2'!$D$4:$D$70,$C31) -> 99.2074 | I31: =_xlfn.MINIFS('2'!$H$4:$H$70,'2'!$C$4:$C$70,$B31,'2'!$D$4:$D$70,$C31) -> 99.2074
A32: 3 | B32: PL-J-11 | C32: PP | D32: =_xlfn.MAXIFS('3'!$I$4:$I$70,'3'!$C$4:$C$70,$B32,'3'!$D$4:$D$70,$C32) -> 6.4747 | E32: =_xlfn.MINIFS('3'!$I$4:$I$70,'3'!$C$4:$C$70,$B32,'3'!$D$4:$D$70,$C32) -> 6.4747 | F32: =_xlfn.MAXIFS('3'!$M$4:$M$70,'3'!$C$4:$C$70,$B32,'3'!$D$4:$D$70,$C32) -> -23.139 | G32: =_xlfn.MINIFS('3'!$M$4:$M$70,'3'!$C$4:$C$70,$B32,'3'!$D$4:$D$70,$C32) -> -39.9734 | H32: =_xlfn.MAXIFS('3'!$H$4:$H$70,'3'!$C$4:$C$70,$B32,'3'!$D$4:$D$70,$C32) -> -257.3633 | I32: =_xlfn.MINIFS('3'!$H$4:$H$70,'3'!$C$4:$C$70,$B32,'3'!$D$4:$D$70,$C32) -> -265.342
A33: 3 | B33: PL-J-11 | C33: SC | D33: =_xlfn.MAXIFS('3'!$I$4:$I$70,'3'!$C$4:$C$70,$B33,'3'!$D$4:$D$70,$C33) -> -2.9462 | E33: =_xlfn.MINIFS('3'!$I$4:$I$70,'3'!$C$4:$C$70,$B33,'3'!$D$4:$D$70,$C33) -> -2.9462 | F33: =_xlfn.MAXIFS('3'!$M$4:$M$70,'3'!$C$4:$C$70,$B33,'3'!$D$4:$D$70,$C33) -> 2.2466 | G33: =_xlfn.MINIFS('3'!$M$4:$M$70,'3'!$C$4:$C$70,$B33,'3'!$D$4:$D$70,$C33) -> -5.4135 | H33: =_xlfn.MAXIFS('3'!$H$4:$H$70,'3'!$C$4:$C$70,$B33,'3'!$D$4:$D$70,$C33) -> -71.5135 | I33: =_xlfn.MINIFS('3'!$H$4:$H$70,'3'!$C$4:$C$70,$B33,'3'!$D$4:$D$70,$C33) -> -71.5135
A34: 3 | B34: PL-J-11 | C34: SX | D34: =_xlfn.MAXIFS('3'!$I$4:$I$70,'3'!$C$4:$C$70,$B34,'3'!$D$4:$D$70,$C34) -> 25.696 | E34: =_xlfn.MINIFS('3'!$I$4:$I$70,'3'!$C$4:$C$70,$B34,'3'!$D$4:$D$70,$C34) -> 25.696 | F34: =_xlfn.MAXIFS('3'!$M$4:$M$70,'3'!$C$4:$C$70,$B34,'3'!$D$4:$D$70,$C34) -> 121.6389 | G34: =_xlfn.MINIFS('3'!$M$4:$M$70,'3'!$C$4:$C$70,$B34,'3'!$D$4:$D$70,$C34) -> 56.1781 | H34: =_xlfn.MAXIFS('3'!$H$4:$H$70,'3'!$C$4:$C$70,$B34,'3'!$D$4:$D$70,$C34) -> 238.636 | I34: =_xlfn.MINIFS('3'!$H$4:$H$70,'3'!$C$4:$C$70,$B34,'3'!$D$4:$D$70,$C34) -> 238.636
A35: 3 | B35: PL-J-11 | C35: SY | D35: =_xlfn.MAXIFS('3'!$I$4:$I$70,'3'!$C$4:$C$70,$B35,'3'!$D$4:$D$70,$C35) -> 23.8413 | E35: =_xlfn.MINIFS('3'!$I$4:$I$70,'3'!$C$4:$C$70,$B35,'3'!$D$4:$D$70,$C35) -> 23.8413 | F35: =_xlfn.MAXIFS('3'!$M$4:$M$70,'3'!$C$4:$C$70,$B35,'3'!$D$4:$D$70,$C35) -> 257.3116 | G35: =_xlfn.MINIFS('3'!$M$4:$M$70,'3'!$C$4:$C$70,$B35,'3'!$D$4:$D$70,$C35) -> 198.5956 | H35: =_xlfn.MAXIFS('3'!$H$4:$H$70,'3'!$C$4:$C$70,$B35,'3'!$D$4:$D$70,$C35) -> 189.4435 | I35: =_xlfn.MINIFS('3'!$H$4:$H$70,'3'!$C$4:$C$70,$B35,'3'!$D$4:$D$70,$C35) -> 189.4435
A36: 3 | B36: PJ2 | C36: PP | D36: =_xlfn.MAXIFS('3'!$I$4:$I$70,'3'!$C$4:$C$70,$B36,'3'!$D$4:$D$70,$C36) -> -27.2143 | E36: =_xlfn.MINIFS('3'!$I$4:$I$70,'3'!$C$4:$C$70,$B36,'3'!$D$4:$D$70,$C36) -> -27.2143 | F36: =_xlfn.MAXIFS('3'!$M$4:$M$70,'3'!$C$4:$C$70,$B36,'3'!$D$4:$D$70,$C36) -> 121.2713 | G36: =_xlfn.MINIFS('3'!$M$4:$M$70,'3'!$C$4:$C$70,$B36,'3'!$D$4:$D$70,$C36) -> 50.5142 | H36: =_xlfn.MAXIFS('3'!$H$4:$H$70,'3'!$C$4:$C$70,$B36,'3'!$D$4:$D$70,$C36) -> -145.9956 | I36: =_xlfn.MINIFS('3'!$H$4:$H$70,'3'!$C$4:$C$70,$B36,'3'!$D$4:$D$70,$C36) -> -154.2831
A37: 3 | B37: PJ2 | C37: SC | D37: =_xlfn.MAXIFS('3'!$I$4:$I$70,'3'!$C$4:$C$70,$B37,'3'!$D$4:$D$70,$C37) -> -8.6232 | E37: =_xlfn.MINIFS('3'!$I$4:$I$70,'3'!$C$4:$C$70,$B37,'3'!$D$4:$D$70,$C37) -> -8.6232 | F37: =_xlfn.MAXIFS('3'!$M$4:$M$70,'3'!$C$4:$C$70,$B37,'3'!$D$4:$D$70,$C37) -> 31.4717 | G37: =_xlfn.MINIFS('3'!$M$4:$M$70,'3'!$C$4:$C$70,$B37,'3'!$D$4:$D$70,$C37) -> 9.0514 | H37: =_xlfn.MAXIFS('3'!$H$4:$H$70,'3'!$C$4:$C$70,$B37,'3'!$D$4:$D$70,$C37) -> -38.2528 | I37: =_xlfn.MINIFS('3'!$H$4:$H$70,'3'!$C$4:$C$70,$B37,'3'!$D$4:$D$70,$C37) -> -38.2528
A38: 3 | B38: PJ2 | C38: SX | D38: =_xlfn.MAXIFS('3'!$I$4:$I$70,'3'!$C$4:$C$70,$B38,'3'!$D$4:$D$70,$C38) -> 28.7636 | E38: =_xlfn.MINIFS('3'!$I$4:$I$70,'3'!$C$4:$C$70,$B38,'3'!$D$4:$D$70,$C38) -> 28.7636 | F38: =_xlfn.MAXIFS('3'!$M$4:$M$70,'3'!$C$4:$C$70,$B38,'3'!$D$4:$D$70,$C38) -> 243.2748 | G38: =_xlfn.MINIFS('3'!$M$4:$M$70,'3'!$C$4:$C$70,$B38,'3'!$D$4:$D$70,$C38) -> 239.3701 | H38: =_xlfn.MAXIFS('3'!$H$4:$H$70,'3'!$C$4:$C$70,$B38,'3'!$D$4:$D$70,$C38) -> 60.7217 | I38: =_xlfn.MINIFS('3'!$H$4:$H$70,'3'!$C$4:$C$70,$B38,'3'!$D$4:$D$70,$C38) -> 60.7217
A39: 3 | B39: PJ2 | C39: SY | D39: =_xlfn.MAXIFS('3'!$I$4:$I$70,'3'!$C$4:$C$70,$B39,'3'!$D$4:$D$70,$C39) -> 13.9832 | E39: =_xlfn.MINIFS('3'!$I$4:$I$70,'3'!$C$4:$C$70,$B39,'3'!$D$4:$D$70,$C39) -> 13.9832 | F39: =_xlfn.MAXIFS('3'!$M$4:$M$70,'3'!$C$4:$C$70,$B39,'3'!$D$4:$D$70,$C39) -> 73.7625 | G39: =_xlfn.MINIFS('3'!$M$4:$M$70,'3'!$C$4:$C$70,$B39,'3'!$D$4:$D$70,$C39) -> 39.5224 | H39: =_xlfn.MAXIFS('3'!$H$4:$H$70,'3'!$C$4:$C$70,$B39,'3'!$D$4:$D$70,$C39) -> 78.393 | I39: =_xlfn.MINIFS('3'!$H$4:$H$70,'3'!$C$4:$C$70,$B39,'3'!$D$4:$D$70,$C39) -> 78.393
A40: 4 | B40: PL-6 | C40: PP | D40: =_xlfn.MAXIFS('4'!$I$4:$I$36,'4'!$C$4:$C$36,$B40,'4'!$D$4:$D$36,$C40) -> -2.7276 | E40: =_xlfn.MINIFS('4'!$I$4:$I$36,'4'!$C$4:$C$36,$B40,'4'!$D$4:$D$36,$C40) -> -2.7276 | F40: =_xlfn.MAXIFS('4'!$M$4:$M$36,'4'!$C$4:$C$36,$B40,'4'!$D$4:$D$36,$C40) -> -57.0829 | G40: =_xlfn.MINIFS('4'!$M$4:$M$36,'4'!$C$4:$C$36,$B40,'4'!$D$4:$D$36,$C40) -> -64.1746 | H40: =_xlfn.MAXIFS('4'!$H$4:$H$36,'4'!$C$4:$C$36,$B40,'4'!$D$4:$D$36,$C40) -> -676.2804 | I40: =_xlfn.MINIFS('4'!$H$4:$H$36,'4'!$C$4:$C$36,$B40,'4'!$D$4:$D$36,$C40) -> -688.1064
A41: 4 | B41: PL-6 | C41: SC | D41: =_xlfn.MAXIFS('4'!$I$4:$I$36,'4'!$C$4:$C$36,$B41,'4'!$D$4:$D$36,$C41) -> -8.4778 | E41: =_xlfn.MINIFS('4'!$I$4:$I$36,'4'!$C$4:$C$36,$B41,'4'!$D$4:$D$36,$C41) -> -8.4778 | F41: =_xlfn.MAXIFS('4'!$M$4:$M$36,'4'!$C$4:$C$36,$B41,'4'!$D$4:$D$36,$C41) -> 2.789 | G41: =_xlfn.MINIFS('4'!$M$4:$M$36,'4'!$C$4:$C$36,$B41,'4'!$D$4:$D$36,$C41) -> -19.2533 | H41: =_xlfn.MAXIFS('4'!$H$4:$H$36,'4'!$C$4:$C$36,$B41,'4'!$D$4:$D$36,$C41) -> -168.2075 | I41: =_xlfn.MINIFS('4'!$H$4:$H$36,'4'!$C$4:$C$36,$B41,'4'!$D$4:$D$36,$C41) -> -168.2075
A42: 4 | B42: PL-6 | C42: SX | D42: =_xlfn.MAXIFS('4'!$I$4:$I$36,'4'!$C$4:$C$36,$B42,'4'!$D$4:$D$36,$C42) -> 5.1077 | E42: =_xlfn.MINIFS('4'!$I$4:$I$36,'4'!$C$4:$C$36,$B42,'4'!$D$4:$D$36,$C42) -> 5.1077 | F42: =_xlfn.MAXIFS('4'!$M$4:$M$36,'4'!$C$4:$C$36,$B42,'4'!$D$4:$D$36,$C42) -> 64.9846 | G42: =_xlfn.MINIFS('4'!$M$4:$M$36,'4'!$C$4:$C$36,$B42,'4'!$D$4:$D$36,$C42) -> 62.44 | H42: =_xlfn.MAXIFS('4'!$H$4:$H$36,'4'!$C$4:$C$36,$B42,'4'!$D$4:$D$36,$C42) -> 69.9837 | I42: =_xlfn.MINIFS('4'!$H$4:$H$36,'4'!$C$4:$C$36,$B42,'4'!$D$4:$D$36,$C42) -> 69.9837
A43: 4 | B43: PL-6 | C43: SY | D43: =_xlfn.MAXIFS('4'!$I$4:$I$36,'4'!$C$4:$C$36,$B43,'4'!$D$4:$D$36,$C43) -> 15.6112 | E43: =_xlfn.MINIFS('4'!$I$4:$I$36,'4'!$C$4:$C$36,$B43,'4'!$D$4:$D$36,$C43) -> 15.6112 | F43: =_xlfn.MAXIFS('4'!$M$4:$M$36,'4'!$C$4:$C$36,$B43,'4'!$D$4:$D$36,$C43) -> 624.0337 | G43: =_xlfn.MINIFS('4'!$M$4:$M$36,'4'!$C$4:$C$36,$B43,'4'!$D$4:$D$36,$C43) -> 590.3302 | H43: =_xlfn.MAXIFS('4'!$H$4:$H$36,'4'!$C$4:$C$36,$B43,'4'!$D$4:$D$36,$C43) -> 158.822 | I43: =_xlfn.MINIFS('4'!$H$4:$H$36,'4'!$C$4:$C$36,$B43,'4'!$D$4:$D$36,$C43) -> 158.822
A44: 5 | B44: PJ1 | C44: PP | D44: =_xlfn.MAXIFS('5'!$I$4:$I$36,'5'!$C$4:$C$36,$B44,'5'!$D$4:$D$36,$C44) -> -2.9777 | E44: =_xlfn.MINIFS('5'!$I$4:$I$36,'5'!$C$4:$C$36,$B44,'5'!$D$4:$D$36,$C44) -> -2.9777 | F44: =_xlfn.MAXIFS('5'!$M$4:$M$36,'5'!$C$4:$C$36,$B44,'5'!$D$4:$D$36,$C44) -> 4.5976 | G44: =_xlfn.MINIFS('5'!$M$4:$M$36,'5'!$C$4:$C$36,$B44,'5'!$D$4:$D$36,$C44) -> -3.1445 | H44: =_xlfn.MAXIFS('5'!$H$4:$H$36,'5'!$C$4:$C$36,$B44,'5'!$D$4:$D$36,$C44) -> -129.5146 | I44: =_xlfn.MINIFS('5'!$H$4:$H$36,'5'!$C$4:$C$36,$B44,'5'!$D$4:$D$36,$C44) -> -133.6115
A45: 5 | B45: PJ1 | C45: SC | D45: =_xlfn.MAXIFS('5'!$I$4:$I$36,'5'!$C$4:$C$36,$B45,'5'!$D$4:$D$36,$C45) -> -0.1626 | E45: =_xlfn.MINIFS('5'!$I$4:$I$36,'5'!$C$4:$C$36,$B45,'5'!$D$4:$D$36,$C45) -> -0.1626 | F45: =_xlfn.MAXIFS('5'!$M$4:$M$36,'5'!$C$4:$C$36,$B45,'5'!$D$4:$D$36,$C45) -> -0.4144 | G45: =_xlfn.MINIFS('5'!$M$4:$M$36,'5'!$C$4:$C$36,$B45,'5'!$D$4:$D$36,$C45) -> -0.8371 | H45: =_xlfn.MAXIFS('5'!$H$4:$H$36,'5'!$C$4:$C$36,$B45,'5'!$D$4:$D$36,$C45) -> -33.6911 | I45: =_xlfn.MINIFS('5'!$H$4:$H$36,'5'!$C$4:$C$36,$B45,'5'!$D$4:$D$36,$C45) -> -33.6911
A46: 5 | B46: PJ1 | C46: SX | D46: =_xlfn.MAXIFS('5'!$I$4:$I$36,'5'!$C$4:$C$36,$B46,'5'!$D$4:$D$36,$C46) -> 11.2979 | E46: =_xlfn.MINIFS('5'!$I$4:$I$36,'5'!$C$4:$C$36,$B46,'5'!$D$4:$D$36,$C46) -> 11.2979 | F46: =_xlfn.MAXIFS('5'!$M$4:$M$36,'5'!$C$4:$C$36,$B46,'5'!$D$4:$D$36,$C46) -> 51.9841 | G46: =_xlfn.MINIFS('5'!$M$4:$M$36,'5'!$C$4:$C$36,$B46,'5'!$D$4:$D$36,$C46) -> 31.9049 | H46: =_xlfn.MAXIFS('5'!$H$4:$H$36,'5'!$C$4:$C$36,$B46,'5'!$D$4:$D$36,$C46) -> 62.8994 | I46: =_xlfn.MINIFS('5'!$H$4:$H$36,'5'!$C$4:$C$36,$B46,'5'!$D$4:$D$36,$C46) -> 62.8994
A47: 5 | B47: PJ1 | C47: SY | D47: =_xlfn.MAXIFS('5'!$I$4:$I$36,'5'!$C$4:$C$36,$B47,'5'!$D$4:$D$36,$C47) -> 5.9106 | E47: =_xlfn.MINIFS('5'!$I$4:$I$36,'5'!$C$4:$C$36,$B47,'5'!$D$4:$D$36,$C47) -> 5.9106 | F47: =_xlfn.MAXIFS('5'!$M$4:$M$36,'5'!$C$4:$C$36,$B47,'5'!$D$4:$D$36,$C47) -> 15.52 | G47: =_xlfn.MINIFS('5'!$M$4:$M$36,'5'!$C$4:$C$36,$B47,'5'!$D$4:$D$36,$C47) -> 1.5723 | H47: =_xlfn.MAXIFS('5'!$H$4:$H$36,'5'!$C$4:$C$36,$B47,'5'!$D$4:$D$36,$C47) -> 29.4812 | I47: =_xlfn.MINIFS('5'!$H$4:$H$36,'5'!$C$4:$C$36,$B47,'5'!$D$4:$D$36,$C47) -> 29.4812
...

Sheet Resumen
A1: Resumen de muros
A3: Pier | B3: Xi (m) | C3: Yi (m) | D3: Xf (m) | E3: Yf (m) | F3: Largo (m) | G3: Espesor (m) | H3: Orientación | I3: # segm.
A4: P1 | B4: =INDEX(Geometría!$V$3:$V$70,MATCH($A4,Geometría!$AB$3:$AB$70,0)) -> 4.401328 | C4: =INDEX(Geometría!$W$3:$W$70,MATCH($A4,Geometría!$AB$3:$AB$70,0)) -> 5.2335349 | D4: {=LOOKUP(2,1/(Geometría!$AB$3:$AB$70=$A4),Geometría!$X$3:$X$70)} -> 4.401328 | E4: {=LOOKUP(2,1/(Geometría!$AB$3:$AB$70=$A4),Geometría!$Y$3:$Y$70)} -> 52.67586 | F4: =SUMIF(Geometría!$AB$3:$AB$70,$A4,Geometría!$Z$3:$Z$70) -> 47.442325 | G4: =INDEX(Geometría!$AA$3:$AA$70,MATCH($A4,Geometría!$AB$3:$AB$70,0)) -> 0.2 | H4: =IFERROR(IF(SUMIF(Geometría!$AB$3:$AB$70,$A4,Geometría!$AC$3:$AC$70)>9*SUMIF(Geometría!$AB$3:$AB$70,$A4,Geometría!$AD$3:$AD$70),"X",IF(SUMIF(Geometría!$AB$3:$AB$70,$A4,Geometría!$AD$3:$AD$70)>9*SUMIF(Geometría!$AB$3:$AB$70,$A4,Geometría!$AC$3:$AC$70),"Y","Diag "&TEXT(DEGREES(ATAN2(SUMIF(Geometría!$AB$3:$AB$70,$A4,Geometría!$AC$3:$AC$70),SUMIF(Geometría!$AB$3:$AB$70,$A4,Geometría!$AD$3:$AD$70))),"0.0")&"°")),"-") -> Y | I4: =COUNTIF(Geometría!$AB$3:$AB$70,$A4) -> 1
A5: PN | B5: =INDEX(Geometría!$V$3:$V$70,MATCH($A5,Geometría!$AB$3:$AB$70,0)) -> 4.401328 | C5: =INDEX(Geometría!$W$3:$W$70,MATCH($A5,Geometría!$AB$3:$AB$70,0)) -> 52.67586 | D5: {=LOOKUP(2,1/(Geometría!$AB$3:$AB$70=$A5),Geometría!$X$3:$X$70)} -> 30.601328 | E5: {=LOOKUP(2,1/(Geometría!$AB$3:$AB$70=$A5),Geometría!$Y$3:$Y$70)} -> 52.67586 | F5: =SUMIF(Geometría!$AB$3:$AB$70,$A5,Geometría!$Z$3:$Z$70) -> 26.2 | G5: =INDEX(Geometría!$AA$3:$AA$70,MATCH($A5,Geometría!$AB$3:$AB$70,0)) -> 0.2 | H5: =IFERROR(IF(SUMIF(Geometría!$AB$3:$AB$70,$A5,Geometría!$AC$3:$AC$70)>9*SUMIF(Geometría!$AB$3:$AB$70,$A5,Geometría!$AD$3:$AD$70),"X",IF(SUMIF(Geometría!$AB$3:$AB$70,$A5,Geometría!$AD$3:$AD$70)>9*SUMIF(Geometría!$AB$3:$AB$70,$A5,Geometría!$AC$3:$AC$70),"Y","Diag "&TEXT(DEGREES(ATAN2(SUMIF(Geometría!$AB$3:$AB$70,$A5,Geometría!$AC$3:$AC$70),SUMIF(Geometría!$AB$3:$AB$70,$A5,Geometría!$AD$3:$AD$70))),"0.0")&"°")),"-") -> X | I5: =COUNTIF(Geometría!$AB$3:$AB$70,$A5) -> 1
A6: P13 | B6: =INDEX(Geometría!$V$3:$V$70,MATCH($A6,Geometría!$AB$3:$AB$70,0)) -> 30.601328 | C6: =INDEX(Geometría!$W$3:$W$70,MATCH($A6,Geometría!$AB$3:$AB$70,0)) -> 52.67586 | D6: {=LOOKUP(2,1/(Geometría!$AB$3:$AB$70=$A6),Geometría!$X$3:$X$70)} -> 30.601328 | E6: {=LOOKUP(2,1/(Geometría!$AB$3:$AB$70=$A6),Geometría!$Y$3:$Y$70)} -> 22.45586 | F6: =SUMIF(Geometría!$AB$3:$AB$70,$A6,Geometría!$Z$3:$Z$70) -> 30.22 | G6: =INDEX(Geometría!$AA$3:$AA$70,MATCH($A6,Geometría!$AB$3:$AB$70,0)) -> 0.2 | H6: =IFERROR(IF(SUMIF(Geometría!$AB$3:$AB$70,$A6,Geometría!$AC$3:$AC$70)>9*SUMIF(Geometría!$AB$3:$AB$70,$A6,Geometría!$AD$3:$AD$70),"X",IF(SUMIF(Geometría!$AB$3:$AB$70,$A6,Geometría!$AD$3:$AD$70)>9*SUMIF(Geometría!$AB$3:$AB$70,$A6,Geometría!$AC$3:$AC$70),"Y","Diag "&TEXT(DEGREES(ATAN2(SUMIF(Geometría!$AB$3:$AB$70,$A6,Geometría!$AC$3:$AC$70),SUMIF(Geometría!$AB$3:$AB$70,$A6,Geometría!$AD$3:$AD$70))),"0.0")&"°")),"-") -> Y | I6: =COUNTIF(Geometría!$AB$3:$AB$70,$A6) -> 1
A7: Plb | B7: =INDEX(Geometría!$V$3:$V$70,MATCH($A7,Geometría!$AB$3:$AB$70,0)) -> 30.601328 | C7: =INDEX(Geometría!$W$3:$W$70,MATCH($A7,Geometría!$AB$3:$AB$70,0)) -> 22.45586 | D7: {=LOOKUP(2,1/(Geometría!$AB$3:$AB$70=$A7),Geometría!$X$3:$X$70)} -> 27.251328 | E7: {=LOOKUP(2,1/(Geometría!$AB$3:$AB$70=$A7),Geometría!$Y$3:$Y$70)} -> 22.45586 | F7: =SUMIF(Geometría!$AB$3:$AB$70,$A7,Geometría!$Z$3:$Z$70) -> 3.35 | G7: =INDEX(Geometría!$AA$3:$AA$70,MATCH($A7,Geometría!$AB$3:$AB$70,0)) -> 0.2 | H7: =IFERROR(IF(SUMIF(Geometría!$AB$3:$AB$70,$A7,Geometría!$AC$3:$AC$70)>9*SUMIF(Geometría!$AB$3:$AB$70,$A7,Geometría!$AD$3:$AD$70),"X",IF(SUMIF(Geometría!$AB$3:$AB$70,$A7,Geometría!$AD$3:$AD$70)>9*SUMIF(Geometría!$AB$3:$AB$70,$A7,Geometría!$AC$3:$AC$70),"Y","Diag "&TEXT(DEGREES(ATAN2(SUMIF(Geometría!$AB$3:$AB$70,$A7,Geometría!$AC$3:$AC$70),SUMIF(Geometría!$AB$3:$AB$70,$A7,Geometría!$AD$3:$AD$70))),"0.0")&"°")),"-") -> X | I7: =COUNTIF(Geometría!$AB$3:$AB$70,$A7) -> 1
A8: P12 | B8: =INDEX(Geometría!$V$3:$V$70,MATCH($A8,Geometría!$AB$3:$AB$70,0)) -> 27.251328 | C8: =INDEX(Geometría!$W$3:$W$70,MATCH($A8,Geometría!$AB$3:$AB$70,0)) -> 22.45586 | D8: {=LOOKUP(2,1/(Geometría!$AB$3:$AB$70=$A8),Geometría!$X$3:$X$70)} -> 27.251328 | E8: {=LOOKUP(2,1/(Geometría!$AB$3:$AB$70=$A8),Geometría!$Y$3:$Y$70)} -> 12.960457 | F8: =SUMIF(Geometría!$AB$3:$AB$70,$A8,Geometría!$Z$3:$Z$70) -> 9.4954031 | G8: =INDEX(Geometría!$AA$3:$AA$70,MATCH($A8,Geometría!$AB$3:$AB$70,0)) -> 0.2 | H8: =IFERROR(IF(SUMIF(Geometría!$AB$3:$AB$70,$A8,Geometría!$AC$3:$AC$70)>9*SUMIF(Geometría!$AB$3:$AB$70,$A8,Geometría!$AD$3:$AD$70),"X",IF(SUMIF(Geometría!$AB$3:$AB$70,$A8,Geometría!$AD$3:$AD$70)>9*SUMIF(Geometría!$AB$3:$AB$70,$A8,Geometría!$AC$3:$AC$70),"Y","Diag "&TEXT(DEGREES(ATAN2(SUMIF(Geometría!$AB$3:$AB$70,$A8,Geometría!$AC$3:$AC$70),SUMIF(Geometría!$AB$3:$AB$70,$A8,Geometría!$AD$3:$AD$70))),"0.0")&"°")),"-") -> Y | I8: =COUNTIF(Geometría!$AB$3:$AB$70,$A8) -> 1
A9: P3-L | B9: =INDEX(Geometría!$V$3:$V$70,MATCH($A9,Geometría!$AB$3:$AB$70,0)) -> 9.891328 | C9: =INDEX(Geometría!$W$3:$W$70,MATCH($A9,Geometría!$AB$3:$AB$70,0)) -> 31.880405 | D9: {=LOOKUP(2,1/(Geometría!$AB$3:$AB$70=$A9),Geometría!$X$3:$X$70)} -> 11.173828 | E9: {=LOOKUP(2,1/(Geometría!$AB$3:$AB$70=$A9),Geometría!$Y$3:$Y$70)} -> 31.880405 | F9: =SUMIF(Geometría!$AB$3:$AB$70,$A9,Geometría!$Z$3:$Z$70) -> 1.2825 | G9: =INDEX(Geometría!$AA$3:$AA$70,MATCH($A9,Geometría!$AB$3:$AB$70,0)) -> 0.25 | H9: =IFERROR(IF(SUMIF(Geometría!$AB$3:$AB$70,$A9,Geometría!$AC$3:$AC$70)>9*SUMIF(Geometría!$AB$3:$AB$70,$A9,Geometría!$AD$3:$AD$70),"X",IF(SUMIF(Geometría!$AB$3:$AB$70,$A9,Geometría!$AD$3:$AD$70)>9*SUMIF(Geometría!$AB$3:$AB$70,$A9,Geometría!$AC$3:$AC$70),"Y","Diag "&TEXT(DEGREES(ATAN2(SUMIF(Geometría!$AB$3:$AB$70,$A9,Geometría!$AC$3:$AC$70),SUMIF(Geometría!$AB$3:$AB$70,$A9,Geometría!$AD$3:$AD$70))),"0.0")&"°")),"-") -> X | I9: =COUNTIF(Geometría!$AB$3:$AB$70,$A9) -> 1
A10: P3-L-J | B10: =INDEX(Geometría!$V$3:$V$70,MATCH($A10,Geometría!$AB$3:$AB$70,0)) -> 9.891328 | C10: =INDEX(Geometría!$W$3:$W$70,MATCH($A10,Geometría!$AB$3:$AB$70,0)) -> 28.080405 | D10: {=LOOKUP(2,1/(Geometría!$AB$3:$AB$70=$A10),Geometría!$X$3:$X$70)} -> 9.891328 | E10: {=LOOKUP(2,1/(Geometría!$AB$3:$AB$70=$A10),Geometría!$Y$3:$Y$70)} -> 31.880405 | F10: =SUMIF(Geometría!$AB$3:$AB$70,$A10,Geometría!$Z$3:$Z$70) -> 3.8 | G10: =INDEX(Geometría!$AA$3:$AA$70,MATCH($A10,Geometría!$AB$3:$AB$70,0)) -> 0.25 | H10: =IFERROR(IF(SUMIF(Geometría!$AB$3:$AB$70,$A10,Geometría!$AC$3:$AC$70)>9*SUMIF(Geometría!$AB$3:$AB$70,$A10,Geometría!$AD$3:$AD$70),"X",IF(SUMIF(Geometría!$AB$3:$AB$70,$A10,Geometría!$AD$3:$AD$70)>9*SUMIF(Geometría!$AB$3:$AB$70,$A10,Geometría!$AC$3:$AC$70),"Y","Diag "&TEXT(DEGREES(ATAN2(SUMIF(Geometría!$AB$3:$AB$70,$A10,Geometría!$AC$3:$AC$70),SUMIF(Geometría!$AB$3:$AB$70,$A10,Geometría!$AD$3:$AD$70))),"0.0")&"°")),"-") -> Y | I10: =COUNTIF(Geometría!$AB$3:$AB$70,$A10) -> 1
A11: PL-6 | B11: =INDEX(Geometría!$V$3:$V$70,MATCH($A11,Geometría!$AB$3:$AB$70,0)) -> 15.519699 | C11: =INDEX(Geometría!$W$3:$W$70,MATCH($A11,Geometría!$AB$3:$AB$70,0)) -> 24.677493 | D11: {=LOOKUP(2,1/(Geometría!$AB$3:$AB$70=$A11),Geometría!$X$3:$X$70)} -> 15.841412 | E11: {=LOOKUP(2,1/(Geometría!$AB$3:$AB$70=$A11),Geometría!$Y$3:$Y$70)} -> 31.880405 | F11: =SUMIF(Geometría!$AB$3:$AB$70,$A11,Geometría!$Z$3:$Z$70) -> 7.2775254 | G11: =INDEX(Geometría!$AA$3:$AA$70,MATCH($A11,Geometría!$AB$3:$AB$70,0)) -> 0.25 | H11: =IFERROR(IF(SUMIF(Geometría!$AB$3:$AB$70,$A11,Geometría!$AC$3:$AC$70)>9*SUMIF(Geometría!$AB$3:$AB$70,$A11,Geometría!$AD$3:$AD$70),"X",IF(SUMIF(Geometría!$AB$3:$AB$70,$A11,Geometría!$AD$3:$AD$70)>9*SUMIF(Geometría!$AB$3:$AB$70,$A11,Geometría!$AC$3:$AC$70),"Y","Diag "&TEXT(DEGREES(ATAN2(SUMIF(Geometría!$AB$3:$AB$70,$A11,Geometría!$AC$3:$AC$70),SUMIF(Geometría!$AB$3:$AB$70,$A11,Geometría!$AD$3:$AD$70))),"0.0")&"°")),"-") -> Y | I11: =COUNTIF(Geometría!$AB$3:$AB$70,$A11) -> 3
A12: PJ2 | B12: =INDEX(Geometría!$V$3:$V$70,MATCH($A12,Geometría!$AB$3:$AB$70,0)) -> 22.249466 | C12: =INDEX(Geometría!$W$3:$W$70,MATCH($A12,Geometría!$AB$3:$AB$70,0)) -> 28.640263 | D12: {=LOOKUP(2,1/(Geometría!$AB$3:$AB$70=$A12),Geometría!$X$3:$X$70)} -> 17.149512 | E12: {=LOOKUP(2,1/(Geometría!$AB$3:$AB$70=$A12),Geometría!$Y$3:$Y$70)} -> 28.640263 | F12: =SUMIF(Geometría!$AB$3:$AB$70,$A12,Geometría!$Z$3:$Z$70) -> 5.099954 | G12: =INDEX(Geometría!$AA$3:$AA$70,MATCH($A12,Geometría!$AB$3:$AB$70,0)) -> 0.25 | H12: =IFERROR(IF(SUMIF(Geometría!$AB$3:$AB$70,$A12,Geometría!$AC$3:$AC$70)>9*SUMIF(Geometría!$AB$3:$AB$70,$A12,Geometría!$AD$3:$AD$70),"X",IF(SUMIF(Geometría!$AB$3:$AB$70,$A12,Geometría!$AD$3:$AD$70)>9*SUMIF(Geometría!$AB$3:$AB$70,$A12,Geometría!$AC$3:$AC$70),"Y","Diag "&TEXT(DEGREES(ATAN2(SUMIF(Geometría!$AB$3:$AB$70,$A12,Geometría!$AC$3:$AC$70),SUMIF(Geometría!$AB$3:$AB$70,$A12,Geometría!$AD$3:$AD$70))),"0.0")&"°")),"-") -> X | I12: =COUNTIF(Geometría!$AB$3:$AB$70,$A12) -> 1
A13: PL-J-11 | B13: =INDEX(Geometría!$V$3:$V$70,MATCH($A13,Geometría!$AB$3:$AB$70,0)) -> 22.249466 | C13: =INDEX(Geometría!$W$3:$W$70,MATCH($A13,Geometría!$AB$3:$AB$70,0)) -> 27.070457 | D13: {=LOOKUP(2,1/(Geometría!$AB$3:$AB$70=$A13),Geometría!$X$3:$X$70)} -> 22.249466 | E13: {=LOOKUP(2,1/(Geometría!$AB$3:$AB$70=$A13),Geometría!$Y$3:$Y$70)} -> 31.980405 | F13: =SUMIF(Geometría!$AB$3:$AB$70,$A13,Geometría!$Z$3:$Z$70) -> 4.909948 | G13: =INDEX(Geometría!$AA$3:$AA$70,MATCH($A13,Geometría!$AB$3:$AB$70,0)) -> 0.25 | H13: =IFERROR(IF(SUMIF(Geometría!$AB$3:$AB$70,$A13,Geometría!$AC$3:$AC$70)>9*SUMIF(Geometría!$AB$3:$AB$70,$A13,Geometría!$AD$3:$AD$70),"X",IF(SUMIF(Geometría!$AB$3:$AB$70,$A13,Geometría!$AD$3:$AD$70)>9*SUMIF(Geometría!$AB$3:$AB$70,$A13,Geometría!$AC$3:$AC$70),"Y","Diag "&TEXT(DEGREES(ATAN2(SUMIF(Geometría!$AB$3:$AB$70,$A13,Geometría!$AC$3:$AC$70),SUMIF(Geometría!$AB$3:$AB$70,$A13,Geometría!$AD$3:$AD$70))),"0.0")&"°")),"-") -> Y | I13: =COUNTIF(Geometría!$AB$3:$AB$70,$A13) -> 2
A14: PJ1 | B14: =INDEX(Geometría!$V$3:$V$70,MATCH($A14,Geometría!$AB$3:$AB$70,0)) -> 9.891328 | C14: =INDEX(Geometría!$W$3:$W$70,MATCH($A14,Geometría!$AB$3:$AB$70,0)) -> 25.524831 | D14: {=LOOKUP(2,1/(Geometría!$AB$3:$AB$70=$A14),Geometría!$X$3:$X$70)} -> 12.412503 | E14: {=LOOKUP(2,1/(Geometría!$AB$3:$AB$70=$A14),Geometría!$Y$3:$Y$70)} -> 25.524831 | F14: =SUMIF(Geometría!$AB$3:$AB$70,$A14,Geometría!$Z$3:$Z$70) -> 2.5211751 | G14: =INDEX(Geometría!$AA$3:$AA$70,MATCH($A14,Geometría!$AB$3:$AB$70,0)) -> 0.25 | H14: =IFERROR(IF(SUMIF(Geometría!$AB$3:$AB$70,$A14,Geometría!$AC$3:$AC$70)>9*SUMIF(Geometría!$AB$3:$AB$70,$A14,Geometría!$AD$3:$AD$70),"X",IF(SUMIF(Geometría!$AB$3:$AB$70,$A14,Geometría!$AD$3:$AD$70)>9*SUMIF(Geometría!$AB$3:$AB$70,$A14,Geometría!$AC$3:$AC$70),"Y","Diag "&TEXT(DEGREES(ATAN2(SUMIF(Geometría!$AB$3:$AB$70,$A14,Geometría!$AC$3:$AC$70),SUMIF(Geometría!$AB$3:$AB$70,$A14,Geometría!$AD$3:$AD$70))),"0.0")&"°")),"-") -> X | I14: =COUNTIF(Geometría!$AB$3:$AB$70,$A14) -> 1
A15: PI | B15: =INDEX(Geometría!$V$3:$V$70,MATCH($A15,Geometría!$AB$3:$AB$70,0)) -> 15.091328 | C15: =INDEX(Geometría!$W$3:$W$70,MATCH($A15,Geometría!$AB$3:$AB$70,0)) -> 22.910457 | D15: {=LOOKUP(2,1/(Geometría!$AB$3:$AB$70=$A15),Geometría!$X$3:$X$70)} -> 9.891328 | E15: {=LOOKUP(2,1/(Geometría!$AB$3:$AB$70=$A15),Geometría!$Y$3:$Y$70)} -> 22.910457 | F15: =SUMIF(Geometría!$AB$3:$AB$70,$A15,Geometría!$Z$3:$Z$70) -> 5.2 | G15: =INDEX(Geometría!$AA$3:$AA$70,MATCH($A15,Geometría!$AB$3:$AB$70,0)) -> 0.25 | H15: =IFERROR(IF(SUMIF(Geometría!$AB$3:$AB$70,$A15,Geometría!$AC$3:$AC$70)>9*SUMIF(Geometría!$AB$3:$AB$70,$A15,Geometría!$AD$3:$AD$70),"X",IF(SUMIF(Geometría!$AB$3:$AB$70,$A15,Geometría!$AD$3:$AD$70)>9*SUMIF(Geometría!$AB$3:$AB$70,$A15,Geometría!$AC$3:$AC$70),"Y","Diag "&TEXT(DEGREES(ATAN2(SUMIF(Geometría!$AB$3:$AB$70,$A15,Geometría!$AC$3:$AC$70),SUMIF(Geometría!$AB$3:$AB$70,$A15,Geometría!$AD$3:$AD$70))),"0.0")&"°")),"-") -> X | I15: =COUNTIF(Geometría!$AB$3:$AB$70,$A15) -> 1
... A24: P5G | B24: =INDEX(Geometría!$V$3:$V$70,MATCH($A24,Geometría!$AB$3:$AB$70,0)) -> 15.091328 | C24: =INDEX(Geometría!$W$3:$W$70,MATCH($A24,Geometría!$AB$3:$AB$70,0)) -> 20.430457 | D24: {=LOOKUP(2,1/(Geometría!$AB$3:$AB$70=$A24),Geometría!$X$3:$X$70)} -> 15.091328 | E24: {=LOOKUP(2,1/(Geometría!$AB$3:$AB$70=$A24),Geometría!$Y$3:$Y$70)} -> 14.990457 | F24: =SUMIF(Geometría!$AB$3:$AB$70,$A24,Geometría!$Z$3:$Z$70) -> 5.44 | G24: =INDEX(Geometría!$AA$3:$AA$70,MATCH($A24,Geometría!$AB$3:$AB$70,0)) -> 0.25 | H24: =IFERROR(IF(SUMIF(Geometría!$AB$3:$AB$70,$A24,Geometría!$AC$3:$AC$70)>9*SUMIF(Geometría!$AB$3:$AB$70,$A24,Geometría!$AD$3:$AD$70),"X",IF(SUMIF(Geometría!$AB$3:$AB$70,$A24,Geometría!$AD$3:$AD$70)>9*SUMIF(Geometría!$AB$3:$AB$70,$A24,Geometría!$AC$3:$AC$70),"Y","Diag "&TEXT(DEGREES(ATAN2(SUMIF(Geometría!$AB$3:$AB$70,$A24,Geometría!$AC$3:$AC$70),SUMIF(Geometría!$AB$3:$AB$70,$A24,Geometría!$AD$3:$AD$70))),"0.0")&"°")),"-") -> Y | I24: =COUNTIF(Geometría!$AB$3:$AB$70,$A24) -> 1
A26: Resumen de columnas
A28: Columna | B28: Xi (m) | C28: Yi (m) | D28: DZ (m) | E28: bx (m) | F28: by (m) | G28: Sección
A29: C1 | B29: =INDEX(Geometría!$D$72:$D$90,MATCH($A29,Geometría!$B$72:$B$90,0))*0.0254 -> 9.891328 | C29: =INDEX(Geometría!$E$72:$E$90,MATCH($A29,Geometría!$B$72:$B$90,0))*0.0254 -> 47.708877 | D29: =INDEX(Geometría!$F$72:$F$90,MATCH($A29,Geometría!$B$72:$B$90,0))*0.0254 -> 2.6 | E29: =IFERROR(VALUE(MID($G29,2,FIND("x",$G29)-2))/100,"") -> 0.3 | F29: =IFERROR(VALUE(TRIM(MID($G29,FIND("x",$G29)+1,FIND(" ",$G29)-FIND("x",$G29)-1)))/100,"") -> 0.5 | G29: =INDEX(Geometría!$C$72:$C$90,MATCH($A29,Geometría!$B$72:$B$90,0)) -> C30x50 G35
A30: C2 | B30: =INDEX(Geometría!$D$72:$D$90,MATCH($A30,Geometría!$B$72:$B$90,0))*0.0254 -> 9.891328 | C30: =INDEX(Geometría!$E$72:$E$90,MATCH($A30,Geometría!$B$72:$B$90,0))*0.0254 -> 42.108877 | D30: =INDEX(Geometría!$F$72:$F$90,MATCH($A30,Geometría!$B$72:$B$90,0))*0.0254 -> 2.6 | E30: =IFERROR(VALUE(MID($G30,2,FIND("x",$G30)-2))/100,"") -> 0.3 | F30: =IFERROR(VALUE(TRIM(MID($G30,FIND("x",$G30)+1,FIND(" ",$G30)-FIND("x",$G30)-1)))/100,"") -> 0.5 | G30: =INDEX(Geometría!$C$72:$C$90,MATCH($A30,Geometría!$B$72:$B$90,0)) -> C30x50 G35
A31: C3 | B31: =INDEX(Geometría!$D$72:$D$90,MATCH($A31,Geometría!$B$72:$B$90,0))*0.0254 -> 9.891328 | C31: =INDEX(Geometría!$E$72:$E$90,MATCH($A31,Geometría!$B$72:$B$90,0))*0.0254 -> 37.108877 | D31: =INDEX(Geometría!$F$72:$F$90,MATCH($A31,Geometría!$B$72:$B$90,0))*0.0254 -> 2.6 | E31: =IFERROR(VALUE(MID($G31,2,FIND("x",$G31)-2))/100,"") -> 0.3 | F31: =IFERROR(VALUE(TRIM(MID($G31,FIND("x",$G31)+1,FIND(" ",$G31)-FIND("x",$G31)-1)))/100,"") -> 0.5 | G31: =INDEX(Geometría!$C$72:$C$90,MATCH($A31,Geometría!$B$72:$B$90,0)) -> C30x50 G35
A32: C4 | B32: =INDEX(Geometría!$D$72:$D$90,MATCH($A32,Geometría!$B$72:$B$90,0))*0.0254 -> 15.841412 | C32: =INDEX(Geometría!$E$72:$E$90,MATCH($A32,Geometría!$B$72:$B$90,0))*0.0254 -> 47.708877 | D32: =INDEX(Geometría!$F$72:$F$90,MATCH($A32,Geometría!$B$72:$B$90,0))*0.0254 -> 2.6 | E32: =IFERROR(VALUE(MID($G32,2,FIND("x",$G32)-2))/100,"") -> 0.3 | F32: =IFERROR(VALUE(TRIM(MID($G32,FIND("x",$G32)+1,FIND(" ",$G32)-FIND("x",$G32)-1)))/100,"") -> 0.5 | G32: =INDEX(Geometría!$C$72:$C$90,MATCH($A32,Geometría!$B$72:$B$90,0)) -> C30x50 G35
A33: C5 | B33: =INDEX(Geometría!$D$72:$D$90,MATCH($A33,Geometría!$B$72:$B$90,0))*0.0254 -> 15.841412 | C33: =INDEX(Geometría!$E$72:$E$90,MATCH($A33,Geometría!$B$72:$B$90,0))*0.0254 -> 42.108877 | D33: =INDEX(Geometría!$F$72:$F$90,MATCH($A33,Geometría!$B$72:$B$90,0))*0.0254 -> 2.6 | E33: =IFERROR(VALUE(MID($G33,2,FIND("x",$G33)-2))/100,"") -> 0.3 | F33: =IFERROR(VALUE(TRIM(MID($G33,FIND("x",$G33)+1,FIND(" ",$G33)-FIND("x",$G33)-1)))/100,"") -> 0.5 | G33: =INDEX(Geometría!$C$72:$C$90,MATCH($A33,Geometría!$B$72:$B$90,0)) -> C30x50 G35
A34: C6 | B34: =INDEX(Geometría!$D$72:$D$90,MATCH($A34,Geometría!$B$72:$B$90,0))*0.0254 -> 15.841412 | C34: =INDEX(Geometría!$E$72:$E$90,MATCH($A34,Geometría!$B$72:$B$90,0))*0.0254 -> 37.108877 | D34: =INDEX(Geometría!$F$72:$F$90,MATCH($A34,Geometría!$B$72:$B$90,0))*0.0254 -> 2.6 | E34: =IFERROR(VALUE(MID($G34,2,FIND("x",$G34)-2))/100,"") -> 0.3 | F34: =IFERROR(VALUE(TRIM(MID($G34,FIND("x",$G34)+1,FIND(" ",$G34)-FIND("x",$G34)-1)))/100,"") -> 0.5 | G34: =INDEX(Geometría!$C$72:$C$90,MATCH($A34,Geometría!$B$72:$B$90,0)) -> C30x50 G35
A35: C7 | B35: =INDEX(Geometría!$D$72:$D$90,MATCH($A35,Geometría!$B$72:$B$90,0))*0.0254 -> 22.249466 | C35: =INDEX(Geometría!$E$72:$E$90,MATCH($A35,Geometría!$B$72:$B$90,0))*0.0254 -> 47.708877 | D35: =INDEX(Geometría!$F$72:$F$90,MATCH($A35,Geometría!$B$72:$B$90,0))*0.0254 -> 2.6 | E35: =IFERROR(VALUE(MID($G35,2,FIND("x",$G35)-2))/100,"") -> 0.3 | F35: =IFERROR(VALUE(TRIM(MID($G35,FIND("x",$G35)+1,FIND(" ",$G35)-FIND("x",$G35)-1)))/100,"") -> 0.5 | G35: =INDEX(Geometría!$C$72:$C$90,MATCH($A35,Geometría!$B$72:$B$90,0)) -> C30x50 G35
A36: C8 | B36: =INDEX(Geometría!$D$72:$D$90,MATCH($A36,Geometría!$B$72:$B$90,0))*0.0254 -> 22.249466 | C36: =INDEX(Geometría!$E$72:$E$90,MATCH($A36,Geometría!$B$72:$B$90,0))*0.0254 -> 42.108877 | D36: =INDEX(Geometría!$F$72:$F$90,MATCH($A36,Geometría!$B$72:$B$90,0))*0.0254 -> 2.6 | E36: =IFERROR(VALUE(MID($G36,2,FIND("x",$G36)-2))/100,"") -> 0.3 | F36: =IFERROR(VALUE(TRIM(MID($G36,FIND("x",$G36)+1,FIND(" ",$G36)-FIND("x",$G36)-1)))/100,"") -> 0.5 | G36: =INDEX(Geometría!$C$72:$C$90,MATCH($A36,Geometría!$B$72:$B$90,0)) -> C30x50 G35
A37: C9 | B37: =INDEX(Geometría!$D$72:$D$90,MATCH($A37,Geometría!$B$72:$B$90,0))*0.0254 -> 22.249466 | C37: =INDEX(Geometría!$E$72:$E$90,MATCH($A37,Geometría!$B$72:$B$90,0))*0.0254 -> 37.108877 | D37: =INDEX(Geometría!$F$72:$F$90,MATCH($A37,Geometría!$B$72:$B$90,0))*0.0254 -> 2.6 | E37: =IFERROR(VALUE(MID($G37,2,FIND("x",$G37)-2))/100,"") -> 0.3 | F37: =IFERROR(VALUE(TRIM(MID($G37,FIND("x",$G37)+1,FIND(" ",$G37)-FIND("x",$G37)-1)))/100,"") -> 0.5 | G37: =INDEX(Geometría!$C$72:$C$90,MATCH($A37,Geometría!$B$72:$B$90,0)) -> C30x50 G35

Sheet Geometría
B2: Pier | C2: SECTION | D2: POINTS | E2: X1 | F2: Y1 | G2: DZ1 | H2: BELOW1 | I2: X2 | J2: Y2 | K2: DZ2 | L2: BELOW2 | M2: X3 | N2: Y3 | O2: DZ3 | P2: BELOW3 | Q2: X4 | R2: Y4 | S2: DZ4 | T2: BELOW4 | V2: Xi (m) | W2: Yi (m) | X2: Xf (m) | Y2: Yf (m) | Z2: Largo seg (m) | AA2: Espesor (m) | AB2: Pier | AC2: |dX| seg | AD2: |dY| seg
B3: P1 | C3: MHA20G35 | D3: 4 | E3: 173.28063 | F3: 206.04468 | G3: 102.3622 | H3: Y | I3: 173.28063 | J3: 2073.8528 | K3: 102.3622 | L3: Y | M3: 173.28063 | N3: 2073.8528 | O3: 0 | P3: N | Q3: 173.28063 | R3: 206.04468 | S3: 0 | T3: N | U3: STRAIGHT | V3: =IF(ISNUMBER($E3),$E3*0.0254,"") -> 4.401328 | W3: =IF(ISNUMBER($F3),$F3*0.0254,"") -> 5.2335349 | X3: =IF(ISNUMBER($I3),$I3*0.0254,"") -> 4.401328 | Y3: =IF(ISNUMBER($J3),$J3*0.0254,"") -> 52.67586 | Z3: =IF(ISNUMBER($E3),SQRT((X3-V3)^2+(Y3-W3)^2),"") -> 47.442325 | AA3: =IFERROR(VALUE(TRIM(MID($C3,4,FIND("G",$C3)-4)))/100,"") -> 0.2 | AB3: =IF(ISNUMBER($E3),$B3,"") -> P1 | AC3: =IF(ISNUMBER($E3),ABS($X3-$V3),"") -> 2.3359092e-12 | AD3: =IF(ISNUMBER($E3),ABS($Y3-$W3),"") -> 47.442325 | AE3: 173.28063 | AF3: 2073.8528 | AG3: 0 | AH3: 173.28063 | AI3: 2073.8528 | AJ3: 102.3622 | AK3: STRAIGHT | AL3: 2 | AM3: 173.28063 | AN3: 2073.8528 | AO3: 102.3622 | AP3: 173.28063 | AQ3: 206.04468 | AR3: 102.3622 | AS3: STRAIGHT | AT3: 2 | AU3: 173.28063 | AV3: 206.04468 | AW3: 102.3622 | AX3: 173.28063 | AY3: 206.04468 | AZ3: 0 | BA3: MESH_DATA | BB3: 0 | BC3: 0
V4: =IF(ISNUMBER($E4),$E4*0.0254,"") | W4: =IF(ISNUMBER($F4),$F4*0.0254,"") | X4: =IF(ISNUMBER($I4),$I4*0.0254,"") | Y4: =IF(ISNUMBER($J4),$J4*0.0254,"") | Z4: =IF(ISNUMBER($E4),SQRT((X4-V4)^2+(Y4-W4)^2),"") | AA4: =IFERROR(VALUE(TRIM(MID($C4,4,FIND("G",$C4)-4)))/100,"") | AB4: =IF(ISNUMBER($E4),$B4,"") | AC4: =IF(ISNUMBER($E4),ABS($X4-$V4),"") | AD4: =IF(ISNUMBER($E4),ABS($Y4-$W4),"")
C5: SECTION | D5: POINTS | E5: X1 | F5: Y1 | G5: DZ1 | H5: BELOW1 | I5: X2 | J5: Y2 | K5: DZ2 | L5: BELOW2 | M5: X3 | N5: Y3 | O5: DZ3 | P5: BELOW3 | Q5: X4 | R5: Y4 | S5: DZ4 | T5: BELOW4 | V5: =IF(ISNUMBER($E5),$E5*0.0254,"") | W5: =IF(ISNUMBER($F5),$F5*0.0254,"") | X5: =IF(ISNUMBER($I5),$I5*0.0254,"") | Y5: =IF(ISNUMBER($J5),$J5*0.0254,"") | Z5: =IF(ISNUMBER($E5),SQRT((X5-V5)^2+(Y5-W5)^2),"") | AA5: =IFERROR(VALUE(TRIM(MID($C5,4,FIND("G",$C5)-4)))/100,"") | AB5: =IF(ISNUMBER($E5),$B5,"") | AC5: =IF(ISNUMBER($E5),ABS($X5-$V5),"") | AD5: =IF(ISNUMBER($E5),ABS($Y5-$W5),"")
B6: PN | C6: MHA20G35 | D6: 4 | E6: 173.28063 | F6: 2073.8528 | G6: 102.3622 | H6: Y | I6: 1204.7767 | J6: 2073.8528 | K6: 102.3622 | L6: Y | M6: 1204.7767 | N6: 2073.8528 | O6: 0 | P6: N | Q6: 173.28063 | R6: 2073.8528 | S6: 0 | T6: N | U6: STRAIGHT | V6: =IF(ISNUMBER($E6),$E6*0.0254,"") -> 4.401328 | W6: =IF(ISNUMBER($F6),$F6*0.0254,"") -> 52.67586 | X6: =IF(ISNUMBER($I6),$I6*0.0254,"") -> 30.601328 | Y6: =IF(ISNUMBER($J6),$J6*0.0254,"") -> 52.67586 | Z6: =IF(ISNUMBER($E6),SQRT((X6-V6)^2+(Y6-W6)^2),"") -> 26.2 | AA6: =IFERROR(VALUE(TRIM(MID($C6,4,FIND("G",$C6)-4)))/100,"") -> 0.2 | AB6: =IF(ISNUMBER($E6),$B6,"") -> PN | AC6: =IF(ISNUMBER($E6),ABS($X6-$V6),"") -> 26.2 | AD6: =IF(ISNUMBER($E6),ABS($Y6-$W6),"") -> 5.0448534e-13 | AE6: 1204.7767 | AF6: 2073.8528 | AG6: 0 | AH6: 1204.7767 | AI6: 2073.8528 | AJ6: 102.3622 | AK6: STRAIGHT | AL6: 2 | AM6: 1204.7767 | AN6: 2073.8528 | AO6: 102.3622 | AP6: 173.28063 | AQ6: 2073.8528 | AR6: 102.3622 | AS6: STRAIGHT | AT6: 2 | AU6: 173.28063 | AV6: 2073.8528 | AW6: 102.3622 | AX6: 173.28063 | AY6: 2073.8528 | AZ6: 0 | BA6: MESH_DATA | BB6: 0 | BC6: 0
V7: =IF(ISNUMBER($E7),$E7*0.0254,"") | W7: =IF(ISNUMBER($F7),$F7*0.0254,"") | X7: =IF(ISNUMBER($I7),$I7*0.0254,"") | Y7: =IF(ISNUMBER($J7),$J7*0.0254,"") | Z7: =IF(ISNUMBER($E7),SQRT((X7-V7)^2+(Y7-W7)^2),"") | AA7: =IFERROR(VALUE(TRIM(MID($C7,4,FIND("G",$C7)-4)))/100,"") | AB7: =IF(ISNUMBER($E7),$B7,"") | AC7: =IF(ISNUMBER($E7),ABS($X7-$V7),"") | AD7: =IF(ISNUMBER($E7),ABS($Y7-$W7),"")
B8: TYPE | C8: SECTION | D8: POINTS | E8: X1 | F8: Y1 | G8: DZ1 | H8: BELOW1 | I8: X2 | J8: Y2 | K8: DZ2 | L8: BELOW2 | M8: X3 | N8: Y3 | O8: DZ3 | P8: BELOW3 | Q8: X4 | R8: Y4 | S8: DZ4 | T8: BELOW4 | V8: =IF(ISNUMBER($E8),$E8*0.0254,"") | W8: =IF(ISNUMBER($F8),$F8*0.0254,"") | X8: =IF(ISNUMBER($I8),$I8*0.0254,"") | Y8: =IF(ISNUMBER($J8),$J8*0.0254,"") | Z8: =IF(ISNUMBER($E8),SQRT((X8-V8)^2+(Y8-W8)^2),"") | AA8: =IFERROR(VALUE(TRIM(MID($C8,4,FIND("G",$C8)-4)))/100,"") | AB8: =IF(ISNUMBER($E8),$B8,"") | AC8: =IF(ISNUMBER($E8),ABS($X8-$V8),"") | AD8: =IF(ISNUMBER($E8),ABS($Y8-$W8),"")
B9: P13 | C9: MHA20G35 | D9: 4 | E9: 1204.7767 | F9: 2073.8528 | G9: 102.3622 | H9: Y | I9: 1204.7767 | J9: 884.08898 | K9: 102.3622 | L9: Y | M9: 1204.7767 | N9: 884.08898 | O9: 0 | P9: N | Q9: 1204.7767 | R9: 2073.8528 | S9: 0 | T9: N | U9: STRAIGHT | V9: =IF(ISNUMBER($E9),$E9*0.0254,"") -> 30.601328 | W9: =IF(ISNUMBER($F9),$F9*0.0254,"") -> 52.67586 | X9: =IF(ISNUMBER($I9),$I9*0.0254,"") -> 30.601328 | Y9: =IF(ISNUMBER($J9),$J9*0.0254,"") -> 22.45586 | Z9: =IF(ISNUMBER($E9),SQRT((X9-V9)^2+(Y9-W9)^2),"") -> 30.22 | AA9: =IFERROR(VALUE(TRIM(MID($C9,4,FIND("G",$C9)-4)))/100,"") -> 0.2 | AB9: =IF(ISNUMBER($E9),$B9,"") -> P13 | AC9: =IF(ISNUMBER($E9),ABS($X9-$V9),"") -> 4.8281379e-12 | AD9: =IF(ISNUMBER($E9),ABS($Y9-$W9),"") -> 30.22 | AE9: 1204.7767 | AF9: 884.08898 | AG9: 0 | AH9: 1204.7767 | AI9: 884.08898 | AJ9: 102.3622 | AK9: STRAIGHT | AL9: 2 | AM9: 1204.7767 | AN9: 884.08898 | AO9: 102.3622 | AP9: 1204.7767 | AQ9: 2073.8528 | AR9: 102.3622 | AS9: STRAIGHT | AT9: 2 | AU9: 1204.7767 | AV9: 2073.8528 | AW9: 102.3622 | AX9: 1204.7767 | AY9: 2073.8528 | AZ9: 0 | BA9: MESH_DATA | BB9: 0 | BC9: 0
V10: =IF(ISNUMBER($E10),$E10*0.0254,"") | W10: =IF(ISNUMBER($F10),$F10*0.0254,"") | X10: =IF(ISNUMBER($I10),$I10*0.0254,"") | Y10: =IF(ISNUMBER($J10),$J10*0.0254,"") | Z10: =IF(ISNUMBER($E10),SQRT((X10-V10)^2+(Y10-W10)^2),"") | AA10: =IFERROR(VALUE(TRIM(MID($C10,4,FIND("G",$C10)-4)))/100,"") | AB10: =IF(ISNUMBER($E10),$B10,"") | AC10: =IF(ISNUMBER($E10),ABS($X10-$V10),"") | AD10: =IF(ISNUMBER($E10),ABS($Y10-$W10),"")
B11: TYPE | C11: SECTION | D11: POINTS | E11: X1 | F11: Y1 | G11: DZ1 | H11: BELOW1 | I11: X2 | J11: Y2 | K11: DZ2 | L11: BELOW2 | M11: X3 | N11: Y3 | O11: DZ3 | P11: BELOW3 | Q11: X4 | R11: Y4 | S11: DZ4 | T11: BELOW4 | V11: =IF(ISNUMBER($E11),$E11*0.0254,"") | W11: =IF(ISNUMBER($F11),$F11*0.0254,"") | X11: =IF(ISNUMBER($I11),$I11*0.0254,"") | Y11: =IF(ISNUMBER($J11),$J11*0.0254,"") | Z11: =IF(ISNUMBER($E11),SQRT((X11-V11)^2+(Y11-W11)^2),"") | AA11: =IFERROR(VALUE(TRIM(MID($C11,4,FIND("G",$C11)-4)))/100,"") | AB11: =IF(ISNUMBER($E11),$B11,"") | AC11: =IF(ISNUMBER($E11),ABS($X11-$V11),"") | AD11: =IF(ISNUMBER($E11),ABS($Y11-$W11),"")
B12: Plb | C12: MHA20G35 | D12: 4 | E12: 1204.7767 | F12: 884.08898 | G12: 102.3622 | H12: Y | I12: 1072.8869 | J12: 884.08898 | K12: 102.3622 | L12: Y | M12: 1072.8869 | N12: 884.08898 | O12: 0 | P12: N | Q12: 1204.7767 | R12: 884.08898 | S12: 0 | T12: N | U12: STRAIGHT | V12: =IF(ISNUMBER($E12),$E12*0.0254,"") -> 30.601328 | W12: =IF(ISNUMBER($F12),$F12*0.0254,"") -> 22.45586 | X12: =IF(ISNUMBER($I12),$I12*0.0254,"") -> 27.251328 | Y12: =IF(ISNUMBER($J12),$J12*0.0254,"") -> 22.45586 | Z12: =IF(ISNUMBER($E12),SQRT((X12-V12)^2+(Y12-W12)^2),"") -> 3.35 | AA12: =IFERROR(VALUE(TRIM(MID($C12,4,FIND("G",$C12)-4)))/100,"") -> 0.2 | AB12: =IF(ISNUMBER($E12),$B12,"") -> Plb | AC12: =IF(ISNUMBER($E12),ABS($X12-$V12),"") -> 3.35 | AD12: =IF(ISNUMBER($E12),ABS($Y12-$W12),"") -> 0 | AE12: 1072.8869 | AF12: 884.08898 | AG12: 0 | AH12: 1072.8869 | AI12: 884.08898 | AJ12: 102.3622 | AK12: STRAIGHT | AL12: 2 | AM12: 1072.8869 | AN12: 884.08898 | AO12: 102.3622 | AP12: 1204.7767 | AQ12: 884.08898 | AR12: 102.3622 | AS12: STRAIGHT | AT12: 2 | AU12: 1204.7767 | AV12: 884.08898 | AW12: 102.3622 | AX12: 1204.7767 | AY12: 884.08898 | AZ12: 0 | BA12: MESH_DATA | BB12: 0 | BC12: 0
V13: =IF(ISNUMBER($E13),$E13*0.0254,"") | W13: =IF(ISNUMBER($F13),$F13*0.0254,"") | X13: =IF(ISNUMBER($I13),$I13*0.0254,"") | Y13: =IF(ISNUMBER($J13),$J13*0.0254,"") | Z13: =IF(ISNUMBER($E13),SQRT((X13-V13)^2+(Y13-W13)^2),"") | AA13: =IFERROR(VALUE(TRIM(MID($C13,4,FIND("G",$C13)-4)))/100,"") | AB13: =IF(ISNUMBER($E13),$B13,"") | AC13: =IF(ISNUMBER($E13),ABS($X13-$V13),"") | AD13: =IF(ISNUMBER($E13),ABS($Y13-$W13),"")
B14: TYPE | C14: SECTION | D14: POINTS | E14: X1 | F14: Y1 | G14: DZ1 | H14: BELOW1 | I14: X2 | J14: Y2 | K14: DZ2 | L14: BELOW2 | M14: X3 | N14: Y3 | O14: DZ3 | P14: BELOW3 | Q14: X4 | R14: Y4 | S14: DZ4 | T14: BELOW4 | V14: =IF(ISNUMBER($E14),$E14*0.0254,"") | W14: =IF(ISNUMBER($F14),$F14*0.0254,"") | X14: =IF(ISNUMBER($I14),$I14*0.0254,"") | Y14: =IF(ISNUMBER($J14),$J14*0.0254,"") | Z14: =IF(ISNUMBER($E14),SQRT((X14-V14)^2+(Y14-W14)^2),"") | AA14: =IFERROR(VALUE(TRIM(MID($C14,4,FIND("G",$C14)-4)))/100,"") | AB14: =IF(ISNUMBER($E14),$B14,"") | AC14: =IF(ISNUMBER($E14),ABS($X14-$V14),"") | AD14: =IF(ISNUMBER($E14),ABS($Y14-$W14),"")
B15: P12 | C15: MHA20G35 | D15: 4 | E15: 1072.8869 | F15: 884.08898 | G15: 102.3622 | H15: Y | I15: 1072.8869 | J15: 510.25422 | K15: 102.3622 | L15: Y | M15: 1072.8869 | N15: 510.25422 | O15: 0 | P15: N | Q15: 1072.8869 | R15: 884.08898 | S15: 0 | T15: N | U15: STRAIGHT | V15: =IF(ISNUMBER($E15),$E15*0.0254,"") -> 27.251328 | W15: =IF(ISNUMBER($F15),$F15*0.0254,"") -> 22.45586 | X15: =IF(ISNUMBER($I15),$I15*0.0254,"") -> 27.251328 | Y15: =IF(ISNUMBER($J15),$J15*0.0254,"") -> 12.960457 | Z15: =IF(ISNUMBER($E15),SQRT((X15-V15)^2+(Y15-W15)^2),"") -> 9.4954031 | AA15: =IFERROR(VALUE(TRIM(MID($C15,4,FIND("G",$C15)-4)))/100,"") -> 0.2 | AB15: =IF(ISNUMBER($E15),$B15,"") -> P12 | AC15: =IF(ISNUMBER($E15),ABS($X15-$V15),"") -> 7.3683282e-12 | AD15: =IF(ISNUMBER($E15),ABS($Y15-$W15),"") -> 9.4954031 | AE15: 1072.8869 | AF15: 510.25422 | AG15: 0 | AH15: 1072.8869 | AI15: 510.25422 | AJ15: 102.3622 | AK15: STRAIGHT | AL15: 2 | AM15: 1072.8869 | AN15: 510.25422 | AO15: 102.3622 | AP15: 1072.8869 | AQ15: 884.08898 | AR15: 102.3622 | AS15: STRAIGHT | AT15: 2 | AU15: 1072.8869 | AV15: 884.08898 | AW15: 102.3622 | AX15: 1072.8869 | AY15: 884.08898 | AZ15: 0 | BA15: MESH_DATA | BB15: 0 | BC15: 0
V16: =IF(ISNUMBER($E16),$E16*0.0254,"") | W16: =IF(ISNUMBER($F16),$F16*0.0254,"") | X16: =IF(ISNUMBER($I16),$I16*0.0254,"") | Y16: =IF(ISNUMBER($J16),$J16*0.0254,"") | Z16: =IF(ISNUMBER($E16),SQRT((X16-V16)^2+(Y16-W16)^2),"") | AA16: =IFERROR(VALUE(TRIM(MID($C16,4,FIND("G",$C16)-4)))/100,"") | AB16: =IF(ISNUMBER($E16),$B16,"") | AC16: =IF(ISNUMBER($E16),ABS($X16-$V16),"") | AD16: =IF(ISNUMBER($E16),ABS($Y16-$W16),"")
B17: TYPE | C17: SECTION | D17: POINTS | E17: X1 | F17: Y1 | G17: DZ1 | H17: BELOW1 | I17: X2 | J17: Y2 | K17: DZ2 | L17: BELOW2 | M17: X3 | N17: Y3 | O17: DZ3 | P17: BELOW3 | Q17: X4 | R17: Y4 | S17: DZ4 | T17: BELOW4 | V17: =IF(ISNUMBER($E17),$E17*0.0254,"") | W17: =IF(ISNUMBER($F17),$F17*0.0254,"") | X17: =IF(ISNUMBER($I17),$I17*0.0254,"") | Y17: =IF(ISNUMBER($J17),$J17*0.0254,"") | Z17: =IF(ISNUMBER($E17),SQRT((X17-V17)^2+(Y17-W17)^2),"") | AA17: =IFERROR(VALUE(TRIM(MID($C17,4,FIND("G",$C17)-4)))/100,"") | AB17: =IF(ISNUMBER($E17),$B17,"") | AC17: =IF(ISNUMBER($E17),ABS($X17-$V17),"") | AD17: =IF(ISNUMBER($E17),ABS($Y17-$W17),"")
B18: P3-L | C18: MHA 25 G35 | D18: 4 | E18: 389.42236 | F18: 1255.1341 | G18: 102.3622 | H18: Y | I18: 439.91449 | J18: 1255.1341 | K18: 102.3622 | L18: Y | M18: 439.91449 | N18: 1255.1341 | O18: 0 | P18: N | Q18: 389.42236 | R18: 1255.1341 | S18: 0 | T18: N | U18: STRAIGHT | V18: =IF(ISNUMBER($E18),$E18*0.0254,"") -> 9.891328 | W18: =IF(ISNUMBER($F18),$F18*0.0254,"") -> 31.880405 | X18: =IF(ISNUMBER($I18),$I18*0.0254,"") -> 11.173828 | Y18: =IF(ISNUMBER($J18),$J18*0.0254,"") -> 31.880405 | Z18: =IF(ISNUMBER($E18),SQRT((X18-V18)^2+(Y18-W18)^2),"") -> 1.2825 | AA18: =IFERROR(VALUE(TRIM(MID($C18,4,FIND("G",$C18)-4)))/100,"") -> 0.25 | AB18: =IF(ISNUMBER($E18),$B18,"") -> P3-L | AC18: =IF(ISNUMBER($E18),ABS($X18-$V18),"") -> 1.2825 | AD18: =IF(ISNUMBER($E18),ABS($Y18-$W18),"") -> 0 | AE18: 439.91449 | AF18: 1255.1341 | AG18: 0 | AH18: 439.91449 | AI18: 1255.1341 | AJ18: 102.3622 | AK18: STRAIGHT | AL18: 2 | AM18: 439.91449 | AN18: 1255.1341 | AO18: 102.3622 | AP18: 389.42236 | AQ18: 1255.1341 | AR18: 102.3622 | AS18: STRAIGHT | AT18: 2 | AU18: 389.42236 | AV18: 1255.1341 | AW18: 102.3622 | AX18: 389.42236 | AY18: 1255.1341 | AZ18: 0 | BA18: MESH_DATA | BB18: 0 | BC18: 0
V19: =IF(ISNUMBER($E19),$E19*0.0254,"") | W19: =IF(ISNUMBER($F19),$F19*0.0254,"") | X19: =IF(ISNUMBER($I19),$I19*0.0254,"") | Y19: =IF(ISNUMBER($J19),$J19*0.0254,"") | Z19: =IF(ISNUMBER($E19),SQRT((X19-V19)^2+(Y19-W19)^2),"") | AA19: =IFERROR(VALUE(TRIM(MID($C19,4,FIND("G",$C19)-4)))/100,"") | AB19: =IF(ISNUMBER($E19),$B19,"") | AC19: =IF(ISNUMBER($E19),ABS($X19-$V19),"") | AD19: =IF(ISNUMBER($E19),ABS($Y19-$W19),"")
B20: TYPE | C20: SECTION | D20: POINTS | E20: X1 | F20: Y1 | G20: DZ1 | H20: BELOW1 | I20: X2 | J20: Y2 | K20: DZ2 | L20: BELOW2 | M20: X3 | N20: Y3 | O20: DZ3 | P20: BELOW3 | Q20: X4 | R20: Y4 | S20: DZ4 | T20: BELOW4 | V20: =IF(ISNUMBER($E20),$E20*0.0254,"") | W20: =IF(ISNUMBER($F20),$F20*0.0254,"") | X20: =IF(ISNUMBER($I20),$I20*0.0254,"") | Y20: =IF(ISNUMBER($J20),$J20*0.0254,"") | Z20: =IF(ISNUMBER($E20),SQRT((X20-V20)^2+(Y20-W20)^2),"") | AA20: =IFERROR(VALUE(TRIM(MID($C20,4,FIND("G",$C20)-4)))/100,"") | AB20: =IF(ISNUMBER($E20),$B20,"") | AC20: =IF(ISNUMBER($E20),ABS($X20-$V20),"") | AD20: =IF(ISNUMBER($E20),ABS($Y20-$W20),"")
B21: P3-L-J | C21: MHA 25 G35 | D21: 4 | E21: 389.42236 | F21: 1105.5278 | G21: 102.3622 | H21: Y | I21: 389.42236 | J21: 1255.1341 | K21: 102.3622 | L21: Y | M21: 389.42236 | N21: 1255.1341 | O21: 0 | P21: N | Q21: 389.42236 | R21: 1105.5278 | S21: 0 | T21: N | U21: STRAIGHT | V21: =IF(ISNUMBER($E21),$E21*0.0254,"") -> 9.891328 | W21: =IF(ISNUMBER($F21),$F21*0.0254,"") -> 28.080405 | X21: =IF(ISNUMBER($I21),$I21*0.0254,"") -> 9.891328 | Y21: =IF(ISNUMBER($J21),$J21*0.0254,"") -> 31.880405 | Z21: =IF(ISNUMBER($E21),SQRT((X21-V21)^2+(Y21-W21)^2),"") -> 3.8 | AA21: =IFERROR(VALUE(TRIM(MID($C21,4,FIND("G",$C21)-4)))/100,"") -> 0.25 | AB21: =IF(ISNUMBER($E21),$B21,"") -> P3-L-J | AC21: =IF(ISNUMBER($E21),ABS($X21-$V21),"") -> 2.9203306e-12 | AD21: =IF(ISNUMBER($E21),ABS($Y21-$W21),"") -> 3.8 | AE21: 389.42236 | AF21: 1255.1341 | AG21: 0 | AH21: 389.42236 | AI21: 1255.1341 | AJ21: 102.3622 | AK21: STRAIGHT | AL21: 2 | AM21: 389.42236 | AN21: 1255.1341 | AO21: 102.3622 | AP21: 389.42236 | AQ21: 1105.5278 | AR21: 102.3622 | AS21: STRAIGHT | AT21: 2 | AU21: 389.42236 | AV21: 1105.5278 | AW21: 102.3622 | AX21: 389.42236 | AY21: 1105.5278 | AZ21: 0 | BA21: MESH_DATA | BB21: 0 | BC21: 0
V22: =IF(ISNUMBER($E22),$E22*0.0254,"") | W22: =IF(ISNUMBER($F22),$F22*0.0254,"") | X22: =IF(ISNUMBER($I22),$I22*0.0254,"") | Y22: =IF(ISNUMBER($J22),$J22*0.0254,"") | Z22: =IF(ISNUMBER($E22),SQRT((X22-V22)^2+(Y22-W22)^2),"") | AA22: =IFERROR(VALUE(TRIM(MID($C22,4,FIND("G",$C22)-4)))/100,"") | AB22: =IF(ISNUMBER($E22),$B22,"") | AC22: =IF(ISNUMBER($E22),ABS($X22-$V22),"") | AD22: =IF(ISNUMBER($E22),ABS($Y22-$W22),"")
B23: TYPE | C23: SECTION | D23: POINTS | E23: X1 | F23: Y1 | G23: DZ1 | H23: BELOW1 | I23: X2 | J23: Y2 | K23: DZ2 | L23: BELOW2 | M23: X3 | N23: Y3 | O23: DZ3 | P23: BELOW3 | Q23: X4 | R23: Y4 | S23: DZ4 | T23: BELOW4 | V23: =IF(ISNUMBER($E23),$E23*0.0254,"") | W23: =IF(ISNUMBER($F23),$F23*0.0254,"") | X23: =IF(ISNUMBER($I23),$I23*0.0254,"") | Y23: =IF(ISNUMBER($J23),$J23*0.0254,"") | Z23: =IF(ISNUMBER($E23),SQRT((X23-V23)^2+(Y23-W23)^2),"") | AA23: =IFERROR(VALUE(TRIM(MID($C23,4,FIND("G",$C23)-4)))/100,"") | AB23: =IF(ISNUMBER($E23),$B23,"") | AC23: =IF(ISNUMBER($E23),ABS($X23-$V23),"") | AD23: =IF(ISNUMBER($E23),ABS($Y23-$W23),"")
B24: PL-6 | C24: MHA 25 G35 | D24: 4 | E24: 611.01176 | F24: 971.55483 | G24: 102.3622 | H24: Y | I24: 623.67766 | J24: 997.39228 | K24: 102.3622 | L24: Y | M24: 623.67766 | N24: 997.39228 | O24: 0 | P24: N | Q24: 611.01176 | R24: 971.55483 | S24: 0 | T24: N | U24: STRAIGHT | V24: =IF(ISNUMBER($E24),$E24*0.0254,"") -> 15.519699 | W24: =IF(ISNUMBER($F24),$F24*0.0254,"") -> 24.677493 | X24: =IF(ISNUMBER($I24),$I24*0.0254,"") -> 15.841412 | Y24: =IF(ISNUMBER($J24),$J24*0.0254,"") -> 25.333764 | Z24: =IF(ISNUMBER($E24),SQRT((X24-V24)^2+(Y24-W24)^2),"") -> 0.73088426 | AA24: =IFERROR(VALUE(TRIM(MID($C24,4,FIND("G",$C24)-4)))/100,"") -> 0.25 | AB24: =IF(ISNUMBER($E24),$B24,"") -> PL-6 | AC24: =IF(ISNUMBER($E24),ABS($X24-$V24),"") -> 0.32171379 | AD24: =IF(ISNUMBER($E24),ABS($Y24-$W24),"") -> 0.65627132 | AE24: 623.67766 | AF24: 997.39228 | AG24: 0 | AH24: 623.67766 | AI24: 997.39228 | AJ24: 102.3622 | AK24: STRAIGHT | AL24: 2 | AM24: 623.67766 | AN24: 997.39228 | AO24: 102.3622 | AP24: 611.01176 | AQ24: 971.55483 | AR24: 102.3622 | AS24: STRAIGHT | AT24: 2 | AU24: 611.01176 | AV24: 971.55483 | AW24: 102.3622 | AX24: 611.01176 | AY24: 971.55483 | AZ24: 0 | BA24: MESH_DATA | BB24: 0 | BC24: 0
